Workbook

Sheet 00_Summary
A1: ตาราง Test Case โครงงาน ระบบจองคอร์ดแบดมินตัน (Book-a-Badminton Court)
A2: ชื่อผู้จัดทำ (ส่งรายบุคคล):
A3: รหัสนักศึกษา:
A4: กลุ่ม / สมาชิกในกลุ่ม:
A5: วันที่จัดทำ:
A6: เวอร์ชันที่ใช้ออกแบบตาราง: | B6: dev commit 0fcde23 (อัปเดตล่าสุด 21 ก.ย. 2569; ก่อนหน้า e9acf4a, b5877f6) — อ้างอิง test.md, backend/src/bookings/booking-time.ts, bookings.service.ts, cron/cron.service.ts, frontend/src/lib/api.ts, frontend/src/lib/booking-display.ts, frontend/src/app/globals.css, frontend/src/app/layout.tsx
A7: เอกสารอ้างอิง Requirement: | B7: feedback.md (กติกาข้อ 1 และ Feature ID A01-A09 / U01-U10 / S01-S06), test.md (Test Checklist ของทีมใน dev), CLAUDE.md, README.md และโค้ดจริงใน backend/src, frontend/src
A8: วิธีบันทึกผล: | B8: ทดสอบจริงแล้วกรอกคอลัมน์ Actual Result และ Status (ผ่าน / ไม่ผ่าน / รอทดสอบ / ตรวจไม่ได้) โดยเลือกจาก dropdown
A9: ข้อกำหนดการทดสอบ: | B9: ใช้ฐานข้อมูลและบัญชีทดสอบเท่านั้น ห้ามใช้ข้อมูลจริงในการทดสอบการยกเลิก/แบน (ตาม CLAUDE.md)
A11: REQ ID | B11: Requirement | C11: แหล่งอ้างอิง | D11: Sheet | E11: จำนวน Test Case | F11: ผ่าน | G11: ไม่ผ่าน | H11: รอทดสอบ
A12: REQ-AUTH | B12: การสมัครสมาชิกและการเข้าสู่ระบบ | C12: ข้อกำหนดช่วงแรก (Auth), auth.service.ts, users.service.ts, jwt.strategy.ts | D12: 01_REQ-AUTH | E12: 32 | F12: =COUNTIF('01_REQ-AUTH'!$G$3:$G$34,"ผ่าน") | G12: =COUNTIF('01_REQ-AUTH'!$G$3:$G$34,"ไม่ผ่าน") | H12: =COUNTIF('01_REQ-AUTH'!$G$3:$G$34,"รอทดสอบ")
A13: REQ-BOOK | B13: การจองคอร์ด: วันต่อวัน โควตา 1 ครั้ง/วัน ตรวจเวลาทับซ้อน | C13: feedback.md กติกาข้อ 1; S01; U02, U03, U04, U10 | D13: 02_REQ-BOOK | E13: 42 | F13: =COUNTIF('02_REQ-BOOK'!$G$3:$G$44,"ผ่าน") | G13: =COUNTIF('02_REQ-BOOK'!$G$3:$G$44,"ไม่ผ่าน") | H13: =COUNTIF('02_REQ-BOOK'!$G$3:$G$44,"รอทดสอบ")
A14: REQ-CANCEL | B14: การยกเลิกการจองเองและเส้นตาย 15 นาทีหลังเวลาเริ่ม | C14: feedback.md กติกาข้อ 1; S02; U07 | D14: 03_REQ-CANCEL | E14: 17 | F14: =COUNTIF('03_REQ-CANCEL'!$G$3:$G$19,"ผ่าน") | G14: =COUNTIF('03_REQ-CANCEL'!$G$3:$G$19,"ไม่ผ่าน") | H14: =COUNTIF('03_REQ-CANCEL'!$G$3:$G$19,"รอทดสอบ")
A15: REQ-CHECKIN | B15: การเช็กอินด้วย QR ของ Admin สถานะการจอง และ Countdown | C15: S03; A07, A08; U06 | D15: 04_REQ-CHECKIN | E15: 28 | F15: =COUNTIF('04_REQ-CHECKIN'!$G$3:$G$30,"ผ่าน") | G15: =COUNTIF('04_REQ-CHECKIN'!$G$3:$G$30,"ไม่ผ่าน") | H15: =COUNTIF('04_REQ-CHECKIN'!$G$3:$G$30,"รอทดสอบ")
A16: REQ-BAN | B16: งานอัตโนมัติตามเวลา นับความผิด แบน 24 ชั่วโมง และปลดแบนอัตโนมัติ | C16: feedback.md กติกาข้อ 1; S02; U08 | D16: 05_REQ-BAN | E16: 26 | F16: =COUNTIF('05_REQ-BAN'!$G$3:$G$28,"ผ่าน") | G16: =COUNTIF('05_REQ-BAN'!$G$3:$G$28,"ไม่ผ่าน") | H16: =COUNTIF('05_REQ-BAN'!$G$3:$G$28,"รอทดสอบ")
A17: REQ-ADMIN | B17: ฟังก์ชันฝั่ง Admin: แจ้งเตือน Dashboard กราฟ Manage Users QR | C17: A01-A09 | D17: 06_REQ-ADMIN | E17: 42 | F17: =COUNTIF('06_REQ-ADMIN'!$G$3:$G$44,"ผ่าน") | G17: =COUNTIF('06_REQ-ADMIN'!$G$3:$G$44,"ไม่ผ่าน") | H17: =COUNTIF('06_REQ-ADMIN'!$G$3:$G$44,"รอทดสอบ")
A18: REQ-UI | B18: UI/UX ธีม Dark/Light Responsive และข้อกำหนดหน้าจอผู้ใช้ | C18: A02, A03, A04; U01, U05, U09, U10; S05, S06 | D18: 07_REQ-UI | E18: 33 | F18: =COUNTIF('07_REQ-UI'!$G$3:$G$35,"ผ่าน") | G18: =COUNTIF('07_REQ-UI'!$G$3:$G$35,"ไม่ผ่าน") | H18: =COUNTIF('07_REQ-UI'!$G$3:$G$35,"รอทดสอบ")
A19: REQ-SEC | B19: ความปลอดภัย: JWT, สิทธิ์ตามบทบาท, ความเป็นเจ้าของข้อมูล | C19: S04; JwtAuthGuard, RolesGuard, jwt.strategy.ts | D19: 08_REQ-SEC | E19: 28 | F19: =COUNTIF('08_REQ-SEC'!$G$3:$G$30,"ผ่าน") | G19: =COUNTIF('08_REQ-SEC'!$G$3:$G$30,"ไม่ผ่าน") | H19: =COUNTIF('08_REQ-SEC'!$G$3:$G$30,"รอทดสอบ")
A20: REQ-CONC | B20: คำขอพร้อมกัน การประมวลผลซ้ำ และความถูกต้องของข้อมูล | C20: S01, S02; checklist ข้อ 4 และข้อ 7 ใน feedback.md | D20: 09_REQ-CONC | E20: 23 | F20: =COUNTIF('09_REQ-CONC'!$G$3:$G$25,"ผ่าน") | G20: =COUNTIF('09_REQ-CONC'!$G$3:$G$25,"ไม่ผ่าน") | H20: =COUNTIF('09_REQ-CONC'!$G$3:$G$25,"รอทดสอบ")
A21: รวม | E21: 271 | F21: =SUM(F12:F20) | G21: =SUM(G12:G20) | H21: =SUM(H12:H20)
A23: หมายเหตุ
A24: 1. ตารางออกแบบโดยแยกตาม Requirement ของโครงงาน โดย 1 Sheet = 1 กลุ่ม Requirement และชื่อ Test Case ID ใช้รูปแบบ TC_<REQ>_<ลำดับ>
A25: 2. แต่ละ Requirement ครอบคลุมกรณีใช้งานทั่วไป (Positive), กรณีผิดพลาด (Negative), ค่าขอบเขต (Boundary) และกรณีพิเศษ (Edge Case) ตามแนวทางตารางตัวอย่าง
A26: 3. คอลัมน์ Status กำหนดค่าได้ 4 แบบ: ผ่าน / ไม่ผ่าน / รอทดสอบ / ตรวจไม่ได้ โดยเลือกจาก dropdown ที่เตรียมไว้
A27: 4. กรณี TEST CASE ที่ต้องใช้เวลา (เส้นตาย 15 นาที, cron, การแบน 24 ชั่วโมง) ให้ปรับเวลาของเครื่องทดสอบหรือเตรียมข้อมูลล่วงหน้า แล้วบันทึกเวลาจริงที่ใช้ทดสอบในคอลัมน์ Actual Result
A28: 5. การทดสอบฝั่ง API ให้แนบหลักฐาน เช่น คำสั่ง curl/Postman, รหัสสถานะ HTTP และผลลัพธ์จริง ลงในคอลัมน์ Actual Result
A29: 6. ปรับตามเวอร์ชัน dev b5877f6: รอบเวลา 15 รอบ (เริ่ม 08:00-22:00 รอบสุดท้ายจบ 23:00), รับเฉพาะเวลาต้นชั่วโมง, ปฏิเสธรอบที่หมดเวลาแล้ว, จองกลางรอบได้แต่ time_out ใช้เวลาสิ้นสุดรอบเดิม, deadline เช็กอิน = max(เวลาเริ่มรอบ, created_at) + 15 นาที, รอบที่ deadline เลยเวลาจบรอบไม่นับ strike, งานอัตโนมัติยกเลิกที่ min(deadline, end) และจบรอบที่เวลาสิ้นสุดรอบ
A30: 7. ก่อนกรอกผลให้ดูชีต 10_Rules_dev (กติกาอ้างอิงจากโค้ดเวอร์ชันปัจจุบัน) และชีต 11_Mapping (จับคู่ Test Case กับชุดทดสอบ test.md ของทีม)
A31: 8. ประเด็นที่ทีมตรวจพบแล้วใน dev (ใช้ประกอบการกรอก Actual Result ไม่ใช่ผลทดสอบของตารางนี้): QA-01..QA-05 validation การสมัคร (ช่องว่าง/studentId ซ้ำเขียนทับบัญชีเดิม [Critical]/email ซ้ำได้ 500/รูปแบบอีเมล), QA-06 เบอร์โทร 16 ตัวกับปีการศึกษาที่ไม่ใช่ตัวเลข, QA-07 สมัครโดยไม่ส่งรหัสผ่านแล้วได้รหัสเริ่มต้น password — หลักฐานอยู่ที่ backend/test/checklist-sections-1-3.cjs และ checklist-sections-1-3-results.json
A32: 9. ประเด็นที่ยังไม่ตรงกันระหว่างเอกสารกับโค้ด (ต้องยืนยันกติกาก่อนตัดสินผ่าน): โควตานับ COMPLETED (GAP-01), availability ที่ไม่ส่ง date ใช้วัน UTC (GAP-05), QR ผู้ดูแลแสดงก่อนเวลาเริ่มรอบหรือไม่ (GAP-03), ปุ่มยืนยันใน popup จองยังใช้ข้อความ 'ยืนยันจองคอร์ท' ไม่ตรงข้อกำหนด U04, A06 กราฟสถิติยังไม่มีโค้ดกราฟในโปรเจกต์
A33: 10. อัปเดตก่อนหน้า (commit e9acf4a / 60a0f24): ไอคอน Material Symbols เปลี่ยนจาก CDN ของ Google มาโหลดจากแพ็กเกจ material-symbols ในโปรเจกต์ (self-hosted) พร้อมแก้ CSS สำหรับ Safari มือถือ, เอกสาร feedback.md ปรับรูปแบบหัวข้อเท่านั้น (ไม่มี Requirement ใหม่), backend/tsconfig.json ปรับ ignoreDeprecations — เพิ่มเคส TC_UI_019 และ TC_UI_020 ให้ตรวจด้านไอคอน/ฟอนต์ที่โหลดจากในเครื่อง
A34: 11. อัปเดตล่าสุด (commit 0fcde23 ของ dev): ตรวจ diff e9acf4a..0fcde23 แล้วไม่มีการเปลี่ยนโค้ดหรือกติกา จึงไม่มี Expected Result ข้อใดเปลี่ยน — รุ่นนี้จึงปรับเฉพาะชีตอ้างอิง: สร้างชีต 11_Mapping ใหม่เป็นตารางตรวจความครบราย ID เทียบ Test Checklist ของทีม (test.md) และตัดการอ้างอิงเอกสารอื่นของทีมออกทั้งหมด
... A37: ผลทดสอบจริง 28/09/2569: เพิ่มรอบโฟกัส REQ-BOOK บน API/MySQL, Chromium และ BookingsService+mocked Date; QA volume แยก; เฉพาะเคสที่ครบทุก assertion จึงนับผ่าน/ไม่ผ่าน
A38: ผ่าน (ทดสอบครบ) | B38: 72 | C38: ไม่ผ่าน (ทดสอบครบ) | D38: 22 | E38: ตรวจบางส่วน/ตรวจไม่ได้ | F38: 38 | G38: ยังรอทดสอบ | H38: 139
A39: ข้อจำกัด: REQ-BOOK ยังเหลือ TC_BOOK_037 รอทดสอบ และ TC_BOOK_009/034/035 ตรวจบางส่วน; กล้อง, โหลดสูง, production HTTPS, หลาย instance และนโยบายอื่นยังอยู่นอกการรันนี้
A40: หลักฐาน REQ-BOOK: testing/evidence/qa_book_*.json; runners: testing/run_qa_book_api.cjs, run_qa_book_ui.cjs, run_qa_book_time.cjs
A41: รอบเพิ่ม 28/09/2569: ทดสอบ 6 เคสจากกลุ่มรอทดสอบเดิมด้วย Chromium + isolated QA backend: ผ่าน 2 (AUTH_012, SEC_011), ไม่ผ่าน 2 (AUTH_030, BOOK_004), ตรวจบางส่วน 2 (UI_001, UI_016); อ้างอิงชีต 13_Execution_Additional
A42: รอบ REQ-BOOK 28/09/2569: 42 เคส — ผ่าน 28, ไม่ผ่าน 10, ตรวจบางส่วน 3, รอทดสอบ 1; ผลรวมทั้ง workbook ผ่าน 72, ไม่ผ่าน 22, ตรวจบางส่วน 38, รอทดสอบ 139 จาก 271

Sheet 01_REQ-AUTH
A1: REQ-AUTH: การสมัครสมาชิกและการเข้าสู่ระบบ (Authentication)
A2: Test Case ID | B2: Test Scenario | C2: Test Steps | D2: Test Data | E2: Expected Result | F2: Actual Result | G2: Status
A3: TC_AUTH_001 | B3: สมัครสมาชิกด้วยข้อมูลครบถ้วนสำเร็จ (Positive) | C3: 1. เปิดหน้า /register 2. กรอกรหัสนักศึกษา ชื่อ-นามสกุล อีเมล เบอร์โทร สาขา ชั้นปี ชื่อผู้ใช้ และรหัสผ่านให้ครบ 3. กดปุ่ม สมัครสมาชิก | D3: รหัส 66010001 / somchai@kmitl.ac.th / somchai_p / Passw0rd!23 / สาขา IT / ชั้นปี 3 | E3: ระบบสร้างบัญชีสำเร็จ แสดงข้อความ "Registration successful!" เก็บ access_token ใน localStorage และพาไปหน้า /dashboard ด้วยสิทธิ์ STUDENT | G3: รอทดสอบ
A4: TC_AUTH_002 | B4: สมัครด้วยอีเมลที่ไม่ใช่โดเมน @kmitl.ac.th (Negative) | C4: 1. เปิดหน้า /register 2. กรอกอีเมล somchai@gmail.com และข้อมูลอื่นครบ 3. กดปุ่ม สมัครสมาชิก | D4: อีเมล somchai@gmail.com | E4: ระบบปฏิเสธการสมัคร ตอบกลับ 400 พร้อมข้อความ "Email must be a @kmitl.ac.th address" และไม่มีบัญชีใหม่ถูกสร้าง | F4: API/MySQL: 400 domain validation Only some workbook assertions were exercised. | G4: ตรวจไม่ได้
A5: TC_AUTH_003 | B5: อีเมลที่ขึ้นต้นถูกแต่ต่อท้ายโดเมนอื่น (Boundary) | C5: 1. เปิดหน้า /register 2. กรอกอีเมล somchai@kmitl.ac.th.co 3. กดปุ่ม สมัครสมาชิก | D5: อีเมล somchai@kmitl.ac.th.co | E5: ระบบปฏิเสธ เพราะต้องลงท้ายด้วย @kmitl.ac.th เท่านั้น และแสดงข้อความแจ้งข้อผิดพลาดที่อ่านเข้าใจได้ | F5: API/MySQL: 400 suffix validation Only some workbook assertions were exercised. | G5: ตรวจไม่ได้
A6: TC_AUTH_004 | B6: สมัครด้วยชื่อผู้ใช้ที่ซ้ำกับที่มีอยู่ (Negative) | C6: 1. สมัครบัญชีใหม่ด้วย username somchai_p (มีอยู่แล้ว) 2. กดปุ่ม สมัครสมาชิก | D6: username somchai_p | E6: ระบบตอบกลับ 400 พร้อมข้อความ "Username already exists" และไม่สร้างบัญชีซ้ำ | F6: API/MySQL: 400 duplicate username Only some workbook assertions were exercised. | G6: ตรวจไม่ได้
A7: TC_AUTH_005 | B7: สมัครด้วยรหัสนักศึกษาที่ซ้ำกับที่มีอยู่ (Negative) | C7: 1. สมัครบัญชีใหม่ด้วย stu_id 66010001 แต่ใช้ username/อีเมลใหม่ 2. กดปุ่ม สมัครสมาชิก | D7: stu_id 66010001, username somchai_two, somchai2@kmitl.ac.th | E7: ระบบไม่บันทึกบัญชีซ้ำ และแจ้งข้อความข้อผิดพลาดที่ผู้ใช้เข้าใจได้ (ต้องไม่ค้างที่ข้อความ 500 แบบดิบ) | F7: API/MySQL: duplicate HTTP 201; original username is OVERWRITTEN 201 !== 400 | G7: ไม่ผ่าน
A8: TC_AUTH_006 | B8: เว้นช่องข้อมูลบังคับว่าง (Negative) | C8: 1. เปิดหน้า /register 2. เว้นช่อง ชื่อผู้ใช้ หรือ รหัสผ่าน ว่าง 3. กดปุ่ม สมัครสมาชิก | D8: ช่องบังคับว่าง 1 ช่อง | E8: ฟอร์มไม่ส่งคำขอไปเซิร์ฟเวอร์ และมีข้อความบอกให้กรอกช่องนั้นให้ครบ | F8: Browser/Chromium: 7 required inputs reject blank before POST; remaining workbook assertions not verified | G8: ตรวจไม่ได้
A9: TC_AUTH_007 | B9: เข้าสู่ระบบด้วยชื่อผู้ใช้และรหัสผ่านถูกต้อง (Positive) | C9: 1. เปิดหน้า /login 2. กรอกบัญชีผู้ใช้ทดสอบที่ seed ไว้ (testuser / password) 3. กดปุ่ม Login | D9: username testuser / password (บัญชี seed ใน users.service.ts) | E9: ระบบตอบกลับ 200 พร้อม access_token และข้อมูลผู้ใช้ (id, username, name, role=STUDENT) แสดงข้อความ "Login successful!" และพาไปหน้า /dashboard | F9: API/MySQL: HTTP 201: 201 !== 200 | G9: ไม่ผ่าน
A10: TC_AUTH_008 | B10: เข้าสู่ระบบด้วยรหัสผ่านผิด (Negative) | C10: 1. เปิดหน้า /login 2. กรอก username testuser และรหัสผ่านผิด 3. กดปุ่ม Login | D10: username testuser / password WrongPass123 | E10: ระบบตอบกลับ 401 พร้อมข้อความ "Invalid credentials" และไม่บันทึก token | F10: API/MySQL: 401, no token Only some workbook assertions were exercised. | G10: ตรวจไม่ได้
A11: TC_AUTH_009 | B11: เข้าสู่ระบบด้วยชื่อผู้ใช้ที่ไม่มีในระบบ (Negative) | C11: 1. เปิดหน้า /login 2. กรอก username no_such_user และรหัสผ่านอะไรก็ได้ 3. กดปุ่ม Login | D11: username no_such_user | E11: ระบบตอบกลับ 401 และไม่เปิดเผยว่ามีหรือไม่มีบัญชีนี้ในข้อความผิดพลาด | F11: API/MySQL: 401 generic message | G11: ผ่าน
A12: TC_AUTH_010 | B12: เข้าสู่ระบบด้วยบัญชี Admin (Positive) | C12: 1. เปิดหน้า /login 2. กรอกบัญชี Admin 3. กดปุ่ม Login | D12: บัญชี Admin ที่ระบบ seed (admin / password ตาม users.service.ts) | E12: ระบบตอบกลับ role=ADMIN โดยใช้ admin_id เป็น id และพาไปหน้า /dashboard ซึ่งมีเมนูสำหรับ Admin | F12: API/MySQL: 201 ADMIN login (API portion; dashboard UI not covered); remaining UI/subcases not exercised Browser/Chromium: admin login -> dashboard with Users menu | G12: ผ่าน
A13: TC_AUTH_011 | B13: ตรวจการจัดเก็บรหัสผ่านในฐานข้อมูล (Security) | C13: 1. สมัครสมาชิกใหม่ 1 บัญชี 2. เปิดฐานข้อมูลตาราง users_students 3. ตรวจค่าคอลัมน์ password ของบัญชีใหม่ | D13: บัญชีที่สมัครใหม่ในข้อ TC_AUTH_001 | E13: คอลัมน์ password เก็บค่าแฮช bcrypt (ขึ้นต้นด้วย $2b$ หรือ $2a$) ไม่เก็บรหัสผ่านแบบข้อความธรรมดา | F13: API/MySQL: bcrypt hash in isolated DB, never raw password | G13: ผ่าน
A14: TC_AUTH_012 | B14: การแนบ token ไปกับคำขอหลังเข้าสู่ระบบ (Positive) | C14: 1. เข้าสู่ระบบสำเร็จ 2. เปิด Developer Tools > Network 3. เรียกหน้า /booking หรือ /bookings/me | D14: access_token ที่ได้จากหน้า login | E14: ทุกคำขอมี header Authorization: Bearer <token> และเซิร์ฟเวอร์ตอบกลับ 200 | F14: Browser/Chromium รอบเพิ่ม: authenticated booking GET requests with Bearer header; availability 200; paths=/api/bookings/me,/api/bookings/user-notifications,/api/bookings/user-notifications,/api/bookings/user-notifications หลักฐาน: testing/evidence/qa_remaining_ui_results.json | G14: ผ่าน
A15: TC_AUTH_013 | B15: ออกจากระบบแล้วใช้หน้าภายในไม่ได้ (Positive) | C15: 1. เข้าสู่ระบบสำเร็จ 2. กด Logout 3. กดปุ่มย้อนกลับของเบราว์เซอร์ไปหน้า /dashboard | D15: บัญชี testuser | E15: ระบบล้าง token ออกจาก localStorage และเมื่อเข้าหน้าภายในจะถูกส่งกลับไปหน้า /login | F15: Browser/Chromium: logout clears storage and protected dashboard redirects | G15: ผ่าน
... A18: TC_AUTH_016 | B18: ส่งรหัสนักศึกษาว่าง ยาวเกิน 8 ตัว หรือผิดรูปแบบ (Negative, REG-07) | C18: 1. ยิง POST /auth/register ด้วย studentId = "" 2. ทำซ้ำด้วย "123456789" (9 ตัว) และ "abcdefgh" 3. ตรวจรหัสสถานะและแถวในฐานข้อมูล | D18: studentId = "", "123456789", "abcdefgh" | E18: ถูกปฏิเสธด้วย validation ที่สื่อความ (4xx) ไม่สร้างบัญชีที่ไม่มีหรือมีรหัสผิดรูปแบบ และไม่เกิด 500 — ปัจจุบัน studentId ว่างได้ 500 ส่วนค่าอื่นได้ 201 (QA-05) | F18: API/MySQL: statuses 500,500,201 | G18: ไม่ผ่าน
A19: TC_AUTH_017 | B19: ชื่อภาษาไทย ชื่อหลายคำ และช่องว่างหัวท้าย (Positive, REG-08) | C19: 1. สมัครด้วย name = " สมชาย ใจดี " 2. เปิด /dashboard และ /admin/users เพื่อดูชื่อที่แสดง 3. ตรวจค่า first_name/last_name ในฐานข้อมูล | D19: name = " สมชาย ใจดี " (ไทย 2 คำ) | E19: ระบบตัดช่องว่างหัวท้าย จัดเก็บ first_name = "สมชาย" และ last_name = "ใจดี" ครบ และแสดงชื่อไทยถูกต้องทุกหน้าโดยไม่หายหรือเป็นอักขระเสีย | G19: รอทดสอบ
A20: TC_AUTH_018 | B20: เบอร์โทรยาวเกินกำหนด และปีการศึกษาที่ไม่ใช่ตัวเลข (Negative, REG-09) | C20: 1. ยิง POST /auth/register ด้วย phone ยาว 16 ตัว 2. ทำซ้ำด้วย year = "abc" 3. ตรวจค่าที่บันทึกจริงในฐานข้อมูล | D20: phone = "0812345678901234", year = "abc" | E20: ระบบตอบ 4xx พร้อมข้อความ validation ของช่องนั้น ไม่บันทึกเบอร์ที่เกินกำหนด และไม่แปลงปีการศึกษาที่ผิดรูปแบบเป็นค่าเริ่มต้นเงียบ ๆ — ปัจจุบันได้ 201 และ year="abc" กลายเป็น 1 (QA-06) | F20: API/MySQL: statuses 500,201 | G20: ไม่ผ่าน
A21: TC_AUTH_019 | B21: ปีการศึกษา 0, ติดลบ, ทศนิยม และเกินช่วง (Boundary, REG-10 [ยืนยันกติกา]) | C21: 1. ยิง POST /auth/register ด้วย year = 0, -1, 1.5 และ 99 ตามลำดับ 2. ตรวจค่าที่บันทึกในฐานข้อมูล 3. เทียบกับช่วงปีการศึกษาที่ทีมตกลง | D21: year = 0, -1, 1.5, 99 (ฐานทดสอบ) | E21: รับเฉพาะปีที่อยู่ในช่วงที่กำหนดและค่าที่บันทึกตรงกับที่ส่ง (ไม่ถูกเปลี่ยนเงียบ ๆ) — ปัจจุบัน 0 → 1, -1 → -1, 1.5 → 1, 99 → 99 จึงต้องยืนยันกติกากับทีมก่อนตัดสินผ่าน/ไม่ผ่าน (ถ้ายังไม่ตกลงให้ใช้ "ตรวจไม่ได้") | G21: รอทดสอบ
A22: TC_AUTH_020 | B22: สมัครโดยไม่ส่งรหัสผ่านหรือส่งรหัสผ่านว่าง (Negative, REG-11) | C22: 1. ยิง POST /auth/register โดยไม่ส่ง field password 2. ทำซ้ำด้วย password = "" 3. ลองล็อกอินด้วย username ที่สร้างและรหัสผ่าน "password" | D22: ไม่ส่ง password / password = "" | E22: ระบบปฏิเสธว่าไม่มีรหัสผ่านและไม่สร้างบัญชี — ปัจจุบันสร้างบัญชีด้วยรหัสผ่านเริ่มต้น "password" (users.service.ts: password || 'password') และล็อกอินด้วยค่านั้นได้ (QA-07 ระดับ High) | F22: API/MySQL: statuses 201,201 | G22: ไม่ผ่าน
A23: TC_AUTH_021 | B23: ความยาวและชนิดอักขระของรหัสผ่าน (Boundary, REG-12 [ยืนยันกติกา]) | C23: 1. สมัครด้วย password ยาว 1 ตัวอักษร 2. ทำซ้ำด้วยรหัสผ่านยาว 100 ตัว และรหัสผ่านที่มีช่องว่าง/อักขระพิเศษ 3. ตรวจข้อความ validation แล้วลองล็อกอินด้วยค่าที่ตั้ง | D23: password = "a", ยาว 100 ตัว, "P@ss w0rd!ไทย" | E23: UI และ API ใช้กติกาความยาว/อักขระชุดเดียวกัน — ปัจจุบัน API รับทั้ง 1 และ 100 ตัวอักษร; ถ้ายังไม่ตกลงกติกาให้บันทึกค่าที่ API ยอมรับจริงและใช้ "ตรวจไม่ได้" | G23: รอทดสอบ
A24: TC_AUTH_022 | B24: username/email ตัวพิมพ์ใหญ่-เล็ก และช่องว่างหัวท้าย (Boundary, REG-13 [ยืนยันกติกา]) | C24: 1. สมัคร username "tee01" สำเร็จ 2. ล็อกอินด้วย "TEE01" และ " tee01 " 3. สมัครซ้ำด้วย username เดิมที่ต่างตัวพิมพ์หรือมีช่องว่าง | D24: username = "tee01", "TEE01", " tee01 " | E24: การตรวจซ้ำและการล็อกอินสอดคล้องกับนโยบายเดียวกัน และต้องไม่สร้างบัญชีซ้ำ — ปัจจุบันบน SQLite ได้ 401 ทั้งสองแบบ ต้องยืนยันซ้ำบน MySQL เพราะ collation ต่างกัน | G24: รอทดสอบ
A25: TC_AUTH_023 | B25: กดสมัครรัวหรือส่งคำขอสมัครเหมือนกันพร้อมกัน (Edge Case, REG-14) | C25: 1. กดปุ่มสมัครรัว ๆ 5 ครั้งบนฟอร์ม 2. ยิง POST /auth/register ด้วย payload เดียวกันพร้อมกัน 2 คำขอ 3. ตรวจจำนวนบัญชีที่ถูกสร้าง | D25: payload เดียวกัน 2–5 คำขอ (ฐานทดสอบ) | E25: สร้างบัญชีได้เพียงบัญชีเดียว คำขอที่เหลือได้ 400 "Username already exists" และไม่มีข้อมูลค้างบางส่วน — ปัจจุบันได้ 201 ทั้งคู่แต่ฐานข้อมูลมีบัญชีเดียว จึงต้องกำหนด contract การตอบคำขอซ้ำ | F25: API/MySQL: Expected values to be strictly deep-equal: + actual - expected [ 201, + 500 - 400 ] | G25: ไม่ผ่าน
A26: TC_AUTH_024 | B26: API สมัครล้มเหลวหรือเครือข่ายหลุดระหว่างส่งฟอร์ม (Edge Case, REG-15) | C26: 1. กรอกฟอร์มสมัครครบแล้วตัดการเชื่อมต่อหรือจำลองเซิร์ฟเวอร์ล้ม 2. กดปุ่มสมัคร 3. เปิดเครือข่ายกลับและกดลองใหม่ | D26: ตัดเครือข่าย / ตอบ 500 ระหว่างส่งฟอร์ม | E26: หน้าจอแจ้งข้อผิดพลาด ไม่รายงานว่าสมัครสำเร็จ ข้อมูลที่กรอกยังอยู่ในช่องให้แก้ไขได้ และกดลองใหม่แล้วได้บัญชีเดียว (frontend/src/app/register/page.tsx เก็บค่าใน state ไม่ล้างฟอร์ม) | G26: รอทดสอบ
A27: TC_AUTH_025 | B27: ส่ง username/password ที่ไม่ใช่ข้อความ (Negative, AUT-04) | C27: 1. ยิง POST /auth/login ด้วย username = "" และ password = "" 2. ทำซ้ำด้วย null, [] และ {} 3. ตรวจรหัสสถานะและข้อความตอบกลับ | D27: username/password = "", null, [], {} | E27: ทุกกรณีตอบ 401 พร้อมข้อความล็อกอินไม่สำเร็จแบบควบคุมได้ ไม่เกิด 500 และไม่คืน stack trace หรือรายละเอียดภายใน (เทียบกับ auth.service.validateUser) | F27: API/MySQL: Expected values to be strictly deep-equal: + actual - expected [ 401, + 500, + 500, 401, - 401, - 401 ] | G27: ไม่ผ่าน
A28: TC_AUTH_026 | B28: รีเฟรชหน้าหลังล็อกอินแล้ว token ยังใช้ได้ (Positive, AUT-06) | C28: 1. ล็อกอินด้วยบัญชีนักศึกษา 2. กด F5 ที่หน้า /dashboard 3. ตรวจว่ายังเป็นบัญชีเดิมและเรียก /bookings/me ได้ | D28: บัญชีนักศึกษาในฐานทดสอบ | E28: หลังรีเฟรชยังคงสถานะล็อกอิน สิทธิ์ STUDENT และข้อมูลเป็นของผู้ใช้เดิม เพราะ api.ts แนบ token จาก localStorage ให้ทุกคำขอ | F28: Browser/Chromium: refresh retains STUDENT and own dashboard | G28: ผ่าน
A29: TC_AUTH_027 | B29: มีหลายคำขอตอบ 401 พร้อมกัน ต้องพากลับ login ครั้งเดียว (Negative, AUT-10) | C29: 1. ล็อกอินแล้วทำให้ token หมดอายุ/ลบทิ้ง 2. เปิดหน้า /dashboard ที่ยิงหลาย API พร้อมกัน 3. สังเกตการเปลี่ยนหน้าและ console | D29: หน้า Dashboard ที่มี polling + /bookings/me + /users/me/ban-status | E29: ล้าง session และพากลับ /login เพียงครั้งเดียว ไม่มี redirect loop ไม่มีคำขอวนไม่สิ้นสุด และไม่เกิด error ซ้ำใน console จากเส้นทางที่จัดการแล้ว (api.ts ใช้ sessionErrors WeakSet กันการรายงานซ้ำ) | G29: รอทดสอบ
A30: TC_AUTH_028 | B30: token ยังถูกต้องแต่บัญชีถูกลบไปแล้ว (Negative, AUT-14) | C30: 1. ล็อกอินด้วยนักศึกษา A และเก็บ token 2. ให้ผู้ดูแลลบบัญชี A (หรือลบในฐานทดสอบ) 3. เรียก /bookings/me และเปิด /dashboard ด้วย token เดิม | D30: token ของบัญชีที่ถูกลบ | E30: API ต้องไม่คืนข้อมูลของบัญชีที่ถูกลบ (jwt.strategy ตรวจผู้ใช้จาก username ทุกครั้ง จึงควรปฏิเสธ) และ frontend ออกจาก session เดิมอย่างเหมาะสม ไม่ค้างที่หน้าเปล่าหรือข้อมูลเก่า | G30: รอทดสอบ
A31: TC_AUTH_029 | B31: ออกจากระบบในแท็บหนึ่ง ต้องใช้งานต่อด้วยบัญชีเดิมในอีกแท็บไม่ได้ (Edge Case, AUT-16) | C31: 1. เปิดระบบสองแท็บด้วยบัญชีเดียวกัน 2. กด logout ที่แท็บแรก 3. กลับมาใช้งานที่แท็บที่สอง (กดปุ่มที่ยิง API) | D31: Chrome 2 แท็บ, บัญชีนักศึกษาเดียวกัน | E31: แท็บที่สองไม่แสดงข้อมูลส่วนตัวต่อ เพราะ token ถูกลบแล้ว คำขอถัดไปได้ 401 และถูกพากลับ /login | G31: รอทดสอบ
A32: TC_AUTH_030 | B32: localStorage ไม่มี user / JSON เสีย / token เป็นข้อความ null (Edge Case, AUT-17) | C32: 1. ตั้งค่า localStorage token = "null" และ user = "{broken" 2. เปิดหน้า /dashboard และ /booking 3. สังเกตหน้าจอและ console | D32: token = "null", user = "{broken" หรือไม่มี key user | E32: เว็บไม่ crash และไม่เกิดหน้าขาว จัดการเป็นยังไม่ล็อกอินและพาไป /login ได้ (จุดที่ parse user คือ MainLayout.tsx และ admin/users/page.tsx) | F32: Browser/Chromium รอบเพิ่ม: /dashboard with broken JSON landed at http://localhost:3001/dashboard, body=error Something went wrong! SyntaxError: Expected property name or '}' in JSON at position 1 (line 1 column 2) SyntaxE + actual - expected + '/dashboard' - '/login' หลักฐาน: testing/evidence/qa_remaining_ui_results.json | G32: ไม่ผ่าน
A33: TC_AUTH_031 | B33: เบราว์เซอร์ไม่อนุญาตให้ใช้ localStorage (Edge Case, AUT-18) | C33: 1. บล็อก localStorage ในเบราว์เซอร์ (ให้การเรียก localStorage โยน exception) 2. เปิด /login และกดเข้าสู่ระบบ 3. สังเกตพฤติกรรมหน้าจอ | D33: เบราว์เซอร์ที่ localStorage ใช้งานไม่ได้ | E33: ระบบมี fallback หรือแจ้งปัญหาให้ผู้ใช้เข้าใจ ไม่ค้างที่สถานะกำลังโหลด และไม่เข้าสู่ระบบแบบครึ่ง ๆ ที่ใช้งานต่อไม่ได้ | G33: รอทดสอบ
A34: TC_AUTH_032 | B34: เปลี่ยนบัญชี A เป็น B ในเบราว์เซอร์เดียวกัน (Edge Case, AUT-19) | C34: 1. ล็อกอินบัญชี A จองคอร์ตแล้วเปิดกระดิ่งดูรายการ 2. ออกจากระบบและล็อกอินบัญชี B 3. เปิด /dashboard และกระดิ่งของ B | D34: บัญชี A และ B ที่มีข้อมูลต่างกัน | E34: B เห็นเฉพาะรายการของ B ทั้งจาก /bookings/me และ /bookings/user-notifications (backend กรองด้วย stu_id จาก token) และไม่มีสถานะแบนหรือรายการของ A ค้างอยู่ | G34: รอทดสอบ

Sheet 02_REQ-BOOK
A1: REQ-BOOK: การจองคอร์ด วันต่อวัน โควตารายวัน และการทับซ้อนของเวลา
A2: Test Case ID | B2: Test Scenario | C2: Test Steps | D2: Test Data | E2: Expected Result | F2: Actual Result | G2: Status
A3: TC_BOOK_001 | B3: จองคอร์ดสำเร็จ (Positive) | C3: 1. เข้าสู่ระบบด้วยบัญชีนักเรียน 2. เปิดหน้า /booking เลือกคอร์ตและรอบเวลา 18:00 3. กดปุ่มจอง แล้วยืนยันในหน้าต่างยืนยันการจอง | D3: court=1, วันที่=วันนี้, startTime=18:00 | E3: ระบบบันทึกการจองสำเร็จ แสดงข้อความ "จองคอร์ทสำเร็จ" และมีรายการใหม่สถานะ PENDING เวลา 18:00-19:00 | F3: Browser/Chromium + MySQL QA: ยืนยันใน dialog สำเร็จ, toast “จองคอร์ทสำเร็จ”; DB บันทึก 18:00-19:00 สถานะ PENDING. หลักฐาน: qa_book_api_results.json; qa_book_ui_results.json; qa_book_ui_recheck_results.json; qa_book_ui_TC_BOOK_017_TC_BOOK_018_TC_BOOK_019.json; qa_book_ui_TC_BOOK_027_TC_BOOK_028.json; qa_book_ui_TC_BOOK_035.json; qa_book_ui_TC_BOOK_041.json; qa_book_time_results.json | G3: ผ่าน
A4: TC_BOOK_002 | B4: ข้อมูลในหน้าต่างยืนยันการจองครบถ้วน (Positive, U04) | C4: 1. เลือกคอร์ตและรอบเวลา แล้วเปิดหน้าต่างยืนยันการจอง 2. ตรวจข้อความในหน้าต่างก่อนกดยืนยัน | D4: court=2, รอบเวลา 20:00 | E4: หน้าต่างยืนยันแสดง วันที่ของวันนี้ เดือน คอร์ต เวลา และชื่อผู้จอง ครบทุกช่อง ตามข้อกำหนด U04 | F4: Browser/Chromium: dialog แสดง วันที่/เดือน/คอร์ท/เวลา/ชื่อผู้จอง ครบ: 28 | กันยายน | Court 2 | 20:00-21:00 | ชื่อบัญชี QA. หลักฐาน: qa_book_api_results.json; qa_book_ui_results.json; qa_book_ui_recheck_results.json; qa_book_ui_TC_BOOK_017_TC_BOOK_018_TC_BOOK_019.json; qa_book_ui_TC_BOOK_027_TC_BOOK_028.json; qa_book_ui_TC_BOOK_035.json; qa_book_ui_TC_BOOK_041.json; qa_book_time_results.json | G4: ผ่าน
A5: TC_BOOK_003 | B5: ชื่อปุ่มยืนยันการจองตามข้อกำหนด U04 (Positive, U04) | C5: 1. เปิดหน้าต่างยืนยันการจอง 2. อ่านชื่อปุ่มยืนยัน | D5: court=2, รอบเวลา 20:00 | E5: ปุ่มยืนยันใช้ข้อความ "จองคอร์ต" ตามข้อกำหนด U04 (ไม่ใช่ "ยืนยันจองคอร์ต") | F5: Browser/Chromium: ปุ่มจริงคือ “ยืนยันจองคอร์ท” ไม่ใช่ข้อความที่ Expected Result กำหนดว่า “จองคอร์ต”. หลักฐาน: qa_book_api_results.json; qa_book_ui_results.json; qa_book_ui_recheck_results.json; qa_book_ui_TC_BOOK_017_TC_BOOK_018_TC_BOOK_019.json; qa_book_ui_TC_BOOK_027_TC_BOOK_028.json; qa_book_ui_TC_BOOK_035.json; qa_book_ui_TC_BOOK_041.json; qa_book_time_results.json | G5: ไม่ผ่าน
A6: TC_BOOK_004 | B6: กดจองโดยยังไม่เลือกรอบเวลา (Negative) | C6: 1. เปิดหน้า /booking 2. ไม่เลือกรอบเวลาใด ๆ 3. กดปุ่มดำเนินการต่อ | D6: ไม่มีการเลือก time slot | E6: ระบบไม่ส่งคำขอ และแสดงข้อความเตือน "กรุณาเลือกรอบเวลาก่อนทำรายการ" | F6: Browser/Chromium รอบเพิ่ม: ปุ่มดำเนินการจองต่อถูกปิดใช้งาน จึงกดเพื่อแสดงข้อความเตือนตาม Expected Result ไม่ได้ true !== false หลักฐาน: testing/evidence/qa_remaining_ui_results.json | G6: ไม่ผ่าน
A7: TC_BOOK_005 | B7: จองวันอื่นนอกจากวันนี้ผ่าน API โดยตรง (Negative, S01) | C7: 1. ใช้ token ของนักเรียนยิง POST /bookings 2. กำหนด date เป็นวันพรุ่งนี้ 3. ตรวจผลลัพธ์ | D7: date=พรุ่งนี้, court=1, startTime=10:00 | E7: ระบบตอบกลับ 400 พร้อมข้อความ "Day-by-day policy: You can only book courts for today." และไม่บันทึกข้อมูล | F7: API/MySQL QA: วันพรุ่งนี้ตอบ 400 ข้อความ day-by-day policy; จำนวนแถว DB 0→0. หลักฐาน: qa_book_api_results.json; qa_book_ui_results.json; qa_book_ui_recheck_results.json; qa_book_ui_TC_BOOK_017_TC_BOOK_018_TC_BOOK_019.json; qa_book_ui_TC_BOOK_027_TC_BOOK_028.json; qa_book_ui_TC_BOOK_035.json; qa_book_ui_TC_BOOK_041.json; qa_book_time_results.json | G7: ผ่าน
A8: TC_BOOK_006 | B8: หน้าจองไม่มีตัวเลือกวันล่วงหน้า (Positive, U02) | C8: 1. เปิดหน้า /booking 2. ตรวจช่องวันที่และตัวเลือกวันที่ 3. กดที่ช่องวันที่ | D8: เปิดหน้า /booking ปกติ | E8: แสดงคำว่า "วันที่" พร้อมวันของวันนี้เท่านั้น ไม่มีช่องให้เลือกวันล่วงหน้าและไม่สามารถแก้เป็นวันอื่นได้ | F8: Browser/Chromium: แสดงวันนี้และคำว่า วันที่; ไม่มี input[type=date] หรือ dropdown ให้เลือกวันอื่น. หลักฐาน: qa_book_api_results.json; qa_book_ui_results.json; qa_book_ui_recheck_results.json; qa_book_ui_TC_BOOK_017_TC_BOOK_018_TC_BOOK_019.json; qa_book_ui_TC_BOOK_027_TC_BOOK_028.json; qa_book_ui_TC_BOOK_035.json; qa_book_ui_TC_BOOK_041.json; qa_book_time_results.json | G8: ผ่าน
A9: TC_BOOK_007 | B9: แสดงเดือนปัจจุบันโดยไม่มี dropdown เลือกเดือน (Positive, U03) | C9: 1. เปิดหน้า /booking 2. ตรวจส่วนแสดงเดือน 3. พยายามกดเลือกเดือน | D9: เปิดหน้า /booking ปกติ | E9: แสดงชื่อเดือนของวันนี้และไม่มี dropdown ให้เปลี่ยนเดือน | F9: Browser/Chromium: current month displayed, no select element | G9: ผ่าน
A10: TC_BOOK_008 | B10: ใช้โควตาวันละ 1 ครั้ง จองรอบที่สองไม่ได้ (Negative, S01) | C10: 1. จองคอร์ต 1 รอบ 18:00 สำเร็จ 2. เลือกคอร์ต 2 รอบ 20:00 แล้วกดจอง 3. ตรวจผลลัพธ์ | D10: ผู้ใช้คนเดิม, court=2, startTime=20:00 | E10: ระบบตอบกลับ 400 พร้อมข้อความ "You already have an active booking. Please complete or cancel it first." และไม่มีการจองใหม่ | F10: API/MySQL: 400 quota | G10: ผ่าน
A11: TC_BOOK_009 | B11: โควตายังถูกนับแม้การจองก่อนหน้าจะ COMPLETED (Boundary, S01) | C11: 1. จองรอบ 08:00 และเช็กอินให้สำเร็จ 2. รอให้ cron เปลี่ยนสถานะเป็น COMPLETED 3. พยายามจองรอบ 20:00 | D11: ผู้ใช้คนเดิม, court=2, startTime=20:00 | E11: ระบบปฏิเสธการจองใหม่ เพราะ COMPLETED ของวันนี้ยังนับเป็นโควตาวันนี้ 1 ครั้ง | F11: Service/API + MySQL QA: เปลี่ยน fixture เป็น COMPLETED แล้วการจองที่ 2 ตอบ 400 และ DB เหลือ 1 แถว; ยังไม่ได้ทำ lifecycle จอง→check-in→cron COMPLETED ครบจริง. หลักฐาน: qa_book_api_results.json; qa_book_ui_results.json; qa_book_ui_recheck_results.json; qa_book_ui_TC_BOOK_017_TC_BOOK_018_TC_BOOK_019.json; qa_book_ui_TC_BOOK_027_TC_BOOK_028.json; qa_book_ui_TC_BOOK_035.json; qa_book_ui_TC_BOOK_041.json; qa_book_time_results.json | G11: ตรวจไม่ได้
A12: TC_BOOK_010 | B12: จองคอร์ตเดียวกันเวลาทับซ้อนกันพอดี (Negative, S01) | C12: 1. ผู้ใช้ A จองคอร์ต 1 เวลา 18:00 สำเร็จ 2. ผู้ใช้ B พยายามจองคอร์ต 1 เวลา 18:00 3. ตรวจผลลัพธ์ | D12: court=1, startTime=18:00 (ผู้ใช้ต่างคน) | E12: ระบบตอบกลับ 400 พร้อมข้อความ "This court is already booked at this time." | F12: API/MySQL: different user, same court/slot 400 | G12: ผ่าน
A13: TC_BOOK_011 | B13: จองคอร์ตเดียวกันเวลาทับซ้อนบางส่วน (Negative, S01) | C13: 1. ผู้ใช้ A จองคอร์ต 1 เวลา 18:00-19:00 2. ผู้ใช้ B พยายามจองคอร์ต 1 เวลา 18:30 3. ตรวจผลลัพธ์ | D13: court=1, startTime=18:30 | E13: ระบบปฏิเสธ 400 เพราะช่วงเวลา 18:30-19:30 ทับซ้อนกับ 18:00-19:00 (ตรวจแบบช่วงเวลาทับซ้อน ไม่ใช่เทียบเวลาเริ่มเท่ากัน) | F13: API/MySQL QA: startTime=18:30 ตอบ 400 “Invalid booking start time.” ตั้งแต่ validation จึงไม่ได้พิสูจน์การชนแบบช่วงเวลา 18:30-19:30 ตาม Expected Result. หลักฐาน: qa_book_api_results.json; qa_book_ui_results.json; qa_book_ui_recheck_results.json; qa_book_ui_TC_BOOK_017_TC_BOOK_018_TC_BOOK_019.json; qa_book_ui_TC_BOOK_027_TC_BOOK_028.json; qa_book_ui_TC_BOOK_035.json; qa_book_ui_TC_BOOK_041.json; qa_book_time_results.json | G13: ไม่ผ่าน
... A38: TC_BOOK_036 | B38: availability โหลดช้า ล้มเหลว หรือได้ข้อมูลว่างผิดปกติ (Negative, AVA-16) | C38: 1. หน่วงหรือทำให้ GET /courts/availability ตอบ 500 2. เปิดหน้าเลือกคอร์ต 3. เปิดเครือข่ายกลับแล้วกดลองใหม่ | D38: ตอบ 500 / หน่วง 10 วินาที / คืนรายการว่าง | E38: หน้าแสดงสถานะกำลังโหลดหรือข้อผิดพลาดที่อ่านเข้าใจ พร้อมปุ่มลองใหม่ และต้องไม่แสดงว่าทุกสนามว่างจนผู้ใช้กดจองแล้วถูกปฏิเสธ (select-court ต้องมี error state และปุ่มโหลดใหม่) | F38: Browser/Chromium จำลอง availability HTTP 500: UI แสดง toast “Failed to load courts” แต่หน้าแสดง 0 คอร์ทพร้อมใช้และไม่มีปุ่มลองใหม่ จึงไม่ผ่าน. หลักฐาน: qa_book_api_results.json; qa_book_ui_results.json; qa_book_ui_recheck_results.json; qa_book_ui_TC_BOOK_017_TC_BOOK_018_TC_BOOK_019.json; qa_book_ui_TC_BOOK_027_TC_BOOK_028.json; qa_book_ui_TC_BOOK_035.json; qa_book_ui_TC_BOOK_041.json; qa_book_time_results.json | G38: ไม่ผ่าน
A39: TC_BOOK_037 | B39: ย้อนหน้าหรือเปลี่ยน query ระหว่างที่คำขอยังไม่กลับมา (Edge Case, AVA-17) | C39: 1. เปิดรอบ 18:00 แล้วเปลี่ยนเป็นรอบ 20:00 ทันที (หรือกดย้อนกลับ) 2. ปล่อยให้คำขอแรกกลับมาช้ากว่าคำขอที่สอง 3. ตรวจรายการคอร์ตที่แสดง | D39: เปลี่ยนจาก 18:00 → 20:00 ภายใน 1 วินาที | E39: หน้าจอแสดงข้อมูลของรอบ 20:00 (คำขอล่าสุด) ไม่ถูกคำขอเก่าทับข้อมูล และไม่จองผิดรอบ | G39: รอทดสอบ
A40: TC_BOOK_038 | B40: ปิด dialog ยืนยันการจองโดยไม่กดยืนยัน (Negative, BKG-02) | C40: 1. เลือกคอร์ตและรอบเวลาให้ dialog ยืนยันเปิดขึ้น 2. กดยกเลิกหรือปิด dialog 3. ตรวจจำนวนรายการจองของผู้ใช้ | D40: Court 1 รอบ 18:00 (ไม่กดยืนยัน) | E40: ไม่มีคำขอ POST /bookings ถูกส่ง ไม่มีรายการใหม่ใน /bookings/me และโควตาของวันนี้ยังว่างอยู่ | F40: Browser/Chromium: ปิด dialog ด้วย “กลับไปเลือก”; POST=0, Booking 0→0, /bookings/me ว่าง และ Court 1 ยังเลือกได้. หลักฐาน: qa_book_api_results.json; qa_book_ui_results.json; qa_book_ui_recheck_results.json; qa_book_ui_TC_BOOK_017_TC_BOOK_018_TC_BOOK_019.json; qa_book_ui_TC_BOOK_027_TC_BOOK_028.json; qa_book_ui_TC_BOOK_035.json; qa_book_ui_TC_BOOK_041.json; qa_book_time_results.json | G40: ผ่าน
A41: TC_BOOK_039 | B41: การจองของวันก่อนไม่กินโควตาวันนี้ (Positive, BKG-08) | C41: 1. เตรียม fixture การจองของเมื่อวาน (PENDING หรือ COMPLETED) ของผู้ใช้ A 2. วันนี้ผู้ใช้ A จองคอร์ตใหม่ 3. ตรวจผลลัพธ์ | D41: ผู้ใช้ A มีการจองเมื่อวาน 1 รายการ, วันนี้ court=3 รอบ 09:00 | E41: จองสำเร็จ 201 เพราะโควตานับเฉพาะรายการที่ booking_date = วันนี้ (การจองของเมื่อวานไม่ถูกนับ) | F41: API/MySQL QA: มี COMPLETED เมื่อวาน แล้ววันนี้จอง Court 3 เวลา 18:00 ได้ 201. หลักฐาน: qa_book_api_results.json; qa_book_ui_results.json; qa_book_ui_recheck_results.json; qa_book_ui_TC_BOOK_017_TC_BOOK_018_TC_BOOK_019.json; qa_book_ui_TC_BOOK_027_TC_BOOK_028.json; qa_book_ui_TC_BOOK_035.json; qa_book_ui_TC_BOOK_041.json; qa_book_time_results.json | G41: ผ่าน
A42: TC_BOOK_040 | B42: ไม่ส่ง date/courtId/startTime หรือส่งชนิดข้อมูลผิด (Negative, BKG-15) | C42: 1. ยิง POST /bookings โดยไม่ส่ง field ทีละช่อง 2. ทำซ้ำด้วย courtId = "abc" และ startTime = 1800 (number) 3. ตรวจรหัสสถานะและข้อความตอบกลับ | D42: ไม่ส่ง field / courtId = "abc" / startTime = 1800 | E42: ได้ controlled 4xx ไม่ใช่ 500 ไม่มีรายการถูกสร้าง และข้อความไม่เปิดเผย stack trace (จุดตรวจคือ regex startTime และการเทียบช่วงเวลาใน bookings.service.ts) | F42: API/MySQL: statuses 500,500,400; booking rows 0 | G42: ไม่ผ่าน
A43: TC_BOOK_041 | B43: เซิร์ฟเวอร์บันทึกสำเร็จแต่ client timeout แล้วลองใหม่ (Edge Case, BKG-17) | C43: 1. ตั้ง timeout ฝั่ง client สั้นมากแล้วยิงจอง 2. ปล่อยให้เซิร์ฟเวอร์บันทึกสำเร็จแต่ client ไม่ได้รับคำตอบ 3. ตรวจ /bookings/me แล้วกดจองซ้ำ | D43: คำขอจองเดียวกัน (court=1, 21:00) | E43: มีรายการจองเพียง 1 รายการในฐานข้อมูล คำขอซ้ำได้ 400 เรื่องโควตารายวัน และผู้ใช้ตรวจพบรายการที่สำเร็จไปแล้วได้จาก /bookings/me | F43: Browser proxy: server commit POST 201 แล้วตัด response ให้ client timeout; UI แจ้ง error, /bookings/me พบ 1 รายการ; retry ตอบ 400 quota; DB มี 1 แถว. หลักฐาน: qa_book_api_results.json; qa_book_ui_results.json; qa_book_ui_recheck_results.json; qa_book_ui_TC_BOOK_017_TC_BOOK_018_TC_BOOK_019.json; qa_book_ui_TC_BOOK_027_TC_BOOK_028.json; qa_book_ui_TC_BOOK_035.json; qa_book_ui_TC_BOOK_041.json; qa_book_time_results.json | G43: ผ่าน
A44: TC_BOOK_042 | B44: transaction ล้มเหลวระหว่างบันทึกการจอง (Edge Case, BKG-18) | C44: 1. จำลองให้การบันทึกล้มกลางทางใน transaction 2. เรียก POST /bookings อีกครั้ง 3. ตรวจว่ามีรายการบางส่วนหรือ lock ค้างหรือไม่ | D44: จำลอง error ระหว่าง transaction (SERIALIZABLE) | E44: ไม่มีรายการจองบางส่วนถูกบันทึก ไม่มี lock ค้างในฐานข้อมูล และคำขอถัดไปทำงานได้ตามปกติ | F44: Mocked transaction + MySQL QA: error ก่อน callback ไม่ทิ้งแถว; คำขอถัดไปบันทึกสำเร็จและไม่พบ lock ค้าง. หลักฐาน: qa_book_api_results.json; qa_book_ui_results.json; qa_book_ui_recheck_results.json; qa_book_ui_TC_BOOK_017_TC_BOOK_018_TC_BOOK_019.json; qa_book_ui_TC_BOOK_027_TC_BOOK_028.json; qa_book_ui_TC_BOOK_035.json; qa_book_ui_TC_BOOK_041.json; qa_book_time_results.json | G44: ผ่าน

Sheet 03_REQ-CANCEL
A1: REQ-CANCEL: การยกเลิกการจองและเส้นตาย 15 นาที
A2: Test Case ID | B2: Test Scenario | C2: Test Steps | D2: Test Data | E2: Expected Result | F2: Actual Result | G2: Status
A3: TC_CANC_001 | B3: ยกเลิกการจองก่อนเส้นตายสำเร็จ (Positive) | C3: 1. จองคอร์ต 1 เวลา 18:00 2. เวลา 18:10 เปิดการจองแล้วกดยกเลิก พร้อมยืนยัน 3. ตรวจสถานะและจำนวนความผิด | D3: booking 18:00, ยกเลิก 18:10 | E3: สถานะเปลี่ยนเป็น CANCELLED แสดงข้อความ "ยกเลิกการจองสำเร็จ" และจำนวนความผิด (strikes) ของผู้ใช้ยังเป็น 0 | G3: รอทดสอบ
A4: TC_CANC_002 | B4: ยกเลิกที่ 18:14:59 ยังไม่นับเป็นความผิด (Boundary) | C4: 1. จองคอร์ต 1 เวลา 18:00 2. ตั้งเวลาเครื่อง/จำลองเวลาเป็น 18:14:59 แล้วกดยกเลิก 3. ตรวจ strikes ในฐานข้อมูล | D4: booking 18:00, ยกเลิก 18:14:59 | E4: การยกเลิกสำเร็จ และ strikes ยังเป็น 0 (ไม่นับเป็นความผิด) | F4: TypeORM/MySQL mocked time: 18:14:59 CANCELLED, strikes=0; only service/cron path, not physical UI | G4: ตรวจไม่ได้
A5: TC_CANC_003 | B5: ยกเลิกที่ 18:15:00 นับเป็นความผิด 1 ครั้ง (Boundary) | C5: 1. จองคอร์ต 1 เวลา 18:00 2. จำลองเวลาเป็น 18:15:00 แล้วกดยกเลิก 3. ตรวจ strikes ในฐานข้อมูล | D5: booking 18:00 (deadline 18:15 ≤ เวลาสิ้นสุดรอบ 19:00), ยกเลิก 18:15:00 | E5: การจองถูกยกเลิกและ strikes เพิ่มเป็น 1 (นับเป็นการยกเลิกสาย 1 ครั้ง) และผู้ใช้ยังไม่ถูกแบน — กติกา dev: นับ strike เฉพาะเมื่อ deadline ไม่เกินเวลาสิ้นสุดรอบ | F5: TypeORM/MySQL mocked time: 18:15:00 CANCELLED, strikes=1, no ban; only service/cron path, not physical UI | G5: ตรวจไม่ได้
A6: TC_CANC_004 | B6: ยกเลิกสายครั้งที่สองแล้วถูกแบนทันที (Positive) | C6: 1. ทำให้เกิดความผิดครั้งที่ 1 จากการยกเลิกสาย 2. ทำให้เกิดความผิดครั้งที่ 2 จากการยกเลิกสายรายการอื่น 3. ตรวจ banned_until ในฐานข้อมูล | D6: ผู้ใช้ 66010001 มี strikes = 1 อยู่ก่อน | E6: ครั้งที่สอง strikes = 2 และ banned_until = เวลาที่เกิดความผิดครั้งที่สอง + 24 ชั่วโมง (86,400,000 มิลลิวินาที) | F6: TypeORM/MySQL mocked time: second late cancel: strikes=2, ban exactly +24h; only service/cron path, not physical UI | G6: ตรวจไม่ได้
A7: TC_CANC_005 | B7: ยกเลิกการจองที่เช็กอินแล้ว (Negative) | C7: 1. จองและเช็กอินสำเร็จ (status = CHECKED_IN) 2. กดยกเลิกการจองรายการนั้น 3. ตรวจผลลัพธ์ | D7: booking ที่มีสถานะ CHECKED_IN | E7: ระบบตอบกลับ 400 พร้อมข้อความ "Cannot cancel. Status is currently CHECKED_IN" และสถานะไม่เปลี่ยน | F7: API/MySQL round 2: HTTP 400, CHECKED_IN unchanged | G7: ผ่าน
A8: TC_CANC_006 | B8: ยกเลิกการจองที่ถูกยกเลิกไปแล้ว (Negative) | C8: 1. ยกเลิกการจองรายการหนึ่งสำเร็จ 2. กดยกเลิกรายการเดิมซ้ำอีกครั้ง 3. ตรวจผลลัพธ์และจำนวนความผิด | D8: booking ที่มีสถานะ CANCELLED | E8: ระบบตอบกลับ 400 พร้อมข้อความ "Cannot cancel. Status is currently CANCELLED" และ strikes ไม่เพิ่มขึ้น | F8: API/MySQL: 400 repeated cancellation | G8: ผ่าน
A9: TC_CANC_007 | B9: ยกเลิกการจองของผู้อื่น (Negative, Security) | C9: 1. เข้าสู่ระบบด้วยบัญชี B 2. เรียก POST /bookings/{id}/cancel ด้วย id ของการจองของบัญชี A 3. ตรวจผลลัพธ์ | D9: booking id ของผู้ใช้ A | E9: ระบบตอบกลับ 404 "Booking not found" และการจองของผู้ใช้ A ยังเป็น PENDING (ไม่ถูกยกเลิก) | F9: API/MySQL: other owner receives 404; booking remains PENDING | G9: ผ่าน
A10: TC_CANC_008 | B10: ยกเลิกด้วยรหัสการจองที่ไม่มีในระบบ (Negative) | C10: 1. เรียก POST /bookings/999999/cancel 2. ตรวจผลลัพธ์ | D10: booking id = 999999 | E10: ระบบตอบกลับ 404 และไม่มีการเปลี่ยนแปลงข้อมูล | F10: API/MySQL: 404 nonexistent booking | G10: ผ่าน
A11: TC_CANC_009 | B11: ยกเลิกทันเวลาแล้วจองใหม่ในวันเดิมได้ (Positive, S01) | C11: 1. จองคอร์ต 1 เวลา 18:00 2. ยกเลิกก่อนเส้นตาย (เช่น 18:10) 3. จองคอร์ต 2 เวลา 20:00 ในวันเดิมอีกครั้ง | D11: court=2, startTime=20:00 | E11: ระบบบันทึกการจองใหม่สำเร็จ (201) เพราะยกเลิกทันเวลาแล้วคืนโควตาของวันนั้น | F11: API/MySQL: 201 rebook after timely cancel | G11: ผ่าน
A12: TC_CANC_010 | B12: ตรวจรายการหลังยกเลิกผ่าน API ของผู้ใช้ (Positive) | C12: 1. ยกเลิกการจองสำเร็จ 2. เรียก GET /bookings/me 3. ตรวจรายการที่ได้ | D12: บัญชีผู้ใช้ที่ทำการยกเลิก | E12: รายการเดิมปรากฏสถานะ CANCELLED และไม่ถูกนับเป็นรายการที่ยังใช้งานอยู่ | F12: API/MySQL: cancelled booking visible in /bookings/me; remaining UI/subcases not exercised | G12: ตรวจไม่ได้
A13: TC_CANC_011 | B13: หน้าจอแสดงเงื่อนไขและเส้นตายการยกเลิกชัดเจน (Positive, U07) | C13: 1. เปิดหน้า /booking (หรือหน้ารายการจอง) 2. อ่านเงื่อนไข/เส้นตายการยกเลิกที่แสดงบนหน้าจอ | D13: เปิดหน้า /booking ปกติ | E13: หน้าจอแสดงเงื่อนไขการยกเลิกและเส้นตายอย่างชัดเจน เช่น ต้องยกเลิกก่อน 15 นาทีหลังเวลาเริ่ม และการยกเลิกสายนับเป็นความผิด 1 ครั้ง ตามข้อกำหนด U07 | G13: รอทดสอบ
A14: TC_CANC_012 | B14: หน้าต่างยืนยันการยกเลิกแสดงข้อมูลการจองครบ (Positive, U07) | C14: 1. กดยกเลิกที่รายการจอง 2. ตรวจหน้าต่างยืนยันก่อนกดยืนยันจริง | D14: รายการจองเวลา 18:00 คอร์ต 1 | E14: หน้าต่างยืนยันแสดงคอร์ต วันที่ เวลา และเงื่อนไข/เส้นตายที่เกี่ยวข้องก่อนให้ผู้ใช้ยืนยัน และยกเลิกได้จริงหลังยืนยัน | G14: รอทดสอบ
A15: TC_CANC_013 | B15: ยกเลิกรอบสั้นที่ deadline เลยเวลาจบรอบ ไม่นับ strike (Boundary, dev) | C15: 1. จองคอร์ต 1 รอบ 10:00 ตอนเวลา 10:50 (deadline 11:05 > เวลาจบรอบ 11:00) 2. ปล่อยเลยเวลาจบรอบแล้วให้ระบบอัตโนมัติจัดการ หรือกดยกเลิกเองหลัง 11:00 3. ตรวจสถานะและ strikes | D15: รอบ 10:00 ที่จองเวลา 10:50 | E15: รายการถูกยกเลิก (CANCELLED) โดยไม่เพิ่ม strike เพราะ deadline เกินเวลาสิ้นสุดรอบ (กติกา dev: รอบสั้นไม่ถูกลงโทษ) | F15: TypeORM/MySQL mocked time: short round end 11:00, no strike; only service/cron path, not physical UI | G15: ตรวจไม่ได้
A16: TC_CANC_014 | B16: ยกเลิกหลัง deadline แต่ก่อนงานอัตโนมัติทำงาน (Positive, dev) | C16: 1. จองคอร์ต 2 รอบ 10:00 2. จำลองเวลา 10:20 (เลย deadline 10:15 แต่ cron ยังไม่รัน) 3. กดยกเลิกและตรวจ strikes | D16: รอบ 10:00, ยกเลิกเวลา 10:20 | E16: สถานะเป็น CANCELLED และ strikes เพิ่มเป็น 1 (ผู้ใช้กดยกเลิกเองสาย จึงนับความผิดทันที ไม่รอ cron) | F16: TypeORM/MySQL mocked time: manual late cancel before cron, strikes=1; only service/cron path, not physical UI | G16: ตรวจไม่ได้
A17: TC_CANC_015 | B17: ยิงยกเลิกรายการเดียวกันพร้อมกันสองคำขอ (Concurrency) | C17: 1. จองคอร์ต 1 รอบ 18:00 ด้วยผู้ใช้ A 2. ยิง POST /bookings/{id}/cancel พร้อมกัน 2 คำขอ 3. ตรวจสถานะและจำนวน strikes | D17: คำขอยกเลิก 2 คำขอพร้อมกันในรายการเดียว | E17: ยกเลิกสำเร็จครั้งเดียว อีกคำขอถูกปฏิเสธอย่างเหมาะสม และ strikes เพิ่มไม่เกิน 1 ครั้ง (ไม่เกิดข้อผิดพลาด transaction) | F17: API/MySQL round 2: concurrent cancel 201/400; CANCELLED, strikes=0 | G17: ผ่าน
A18: TC_CANC_016 | B18: ยกเลิกล้มเหลวจากเครือข่าย หน้าจอต้องไม่รายงานว่าสำเร็จ (Edge Case) | C18: 1. จำลองให้คำขอยกเลิกล้มเหลว (ตัดเครือข่าย/ให้เซิร์ฟเวอร์ตอบ 500) 2. กดยกเลิกและยืนยัน 3. ตรวจข้อความบนหน้าจอ สถานะปุ่ม และสถานะจริงในฐานข้อมูล | D18: คำขอยกเลิกล้มเหลว 1 ครั้ง | E18: หน้าจอไม่แสดงว่ายกเลิกสำเร็จ สถานะการจองยังเป็น PENDING และผู้ใช้กดลองใหม่ได้หลังเครือข่ายกลับมา | G18: รอทดสอบ
A19: TC_CANC_017 | B19: เปิด dialog ยกเลิกแล้วไม่กดยืนยัน (Positive, CAN-01) | C19: 1. เปิด dialog ยกเลิกการจอง PENDING ของวันนี้ 2. กดยกเลิกหรือปิด dialog โดยไม่ยืนยัน 3. ตรวจสถานะรายการและจำนวน strikes ที่ /bookings/me | D19: booking PENDING รอบ 18:00 (ยังไม่ถึง deadline) | E19: รายการยังเป็น PENDING และ strikes ไม่เพิ่ม เพราะยังไม่มีการเรียก POST /bookings/{id}/cancel จนกว่าจะยืนยันใน dialog | G19: รอทดสอบ

Sheet 04_REQ-CHECKIN
A1: REQ-CHECKIN: การเช็กอินด้วย QR สถานะการจอง และ Countdown
A2: Test Case ID | B2: Test Scenario | C2: Test Steps | D2: Test Data | E2: Expected Result | F2: Actual Result | G2: Status
A3: TC_CHK_001 | B3: Admin แสดง QR ประจำคอร์ตบน Dashboard (Positive, A07) | C3: 1. เข้าสู่ระบบด้วยบัญชี Admin 2. เปิดหน้า /dashboard และเลือกคอร์ตที่ต้องการ 3. ตรวจว่าแสดง QR Code ของคอร์ตนั้น | D3: บัญชี Admin ที่ระบบ seed (admin / password ตาม users.service.ts) | E3: หน้าจอแสดง QR Code ของคอร์ตนั้นจริง และนำไปสแกนด้วยอุปกรณ์อื่นได้ โดยค่าใน QR คือหมายเลขคอร์ต | G3: รอทดสอบ
A4: TC_CHK_002 | B4: User สแกน QR และเช็กอินสำเร็จในเวลาที่อนุญาต (Positive, U06) | C4: 1. จองคอร์ต 2 เวลา 18:00 2. เปิดหน้า /scan แล้วสแกน QR ของคอร์ต 2 ภายใน 15 นาทีก่อนเวลาเริ่ม 3. ตรวจผลลัพธ์ | D4: court=2, สแกนเวลา 17:50 (ช่วงที่อนุญาต 17:45 ถึง 18:14:59) | E4: ระบบตอบกลับสำเร็จ แสดงข้อความ "Check-in successful! Enjoy your game." พาไปหน้า /dashboard และสถานะการจองเป็น CHECKED_IN (กติกา dev: เช็กอินได้ตั้งแต่ 15 นาทีก่อนเวลาเริ่มรอบ จนถึง deadline = max(เวลาเริ่มรอบ, เวลาสร้างการจอง) + 15 นาที) | G4: รอทดสอบ
A5: TC_CHK_003 | B5: สแกนเช็กอินเร็วเกิน 15 นาทีก่อนเวลาเริ่ม (Negative, Boundary) | C5: 1. จองคอร์ต 2 เวลา 18:00 2. สแกน QR ของคอร์ต 2 เวลา 17:44 3. ตรวจผลลัพธ์ | D5: court=2, สแกนเวลา 17:44 | E5: ระบบตอบกลับ 400 พร้อมข้อความ "You cannot check in more than 15 minutes before the booking time starts." และสถานะยังเป็น PENDING | F5: API/MySQL round 2: early check-in rejected before 14:00 (only part of workbook case exercised) | G5: ตรวจไม่ได้
A6: TC_CHK_004 | B6: สแกนที่เวลาขอบ 15 นาทีพอดียังเช็กอินได้ (Boundary) | C6: 1. จองคอร์ต 2 เวลา 18:00 2. สแกน QR ของคอร์ต 2 เวลา 17:45:00 พอดี 3. ตรวจผลลัพธ์ | D6: court=2, สแกนเวลา 17:45:00 | E6: ระบบยอมรับการเช็กอินที่ขอบเวลา 15 นาทีพอดี (17:45) และสถานะเปลี่ยนเป็น CHECKED_IN | F6: TypeORM/MySQL mocked time: 17:45:00 accepted; no camera scan; only service/cron path, not physical UI | G6: ตรวจไม่ได้
A7: TC_CHK_005 | B7: สแกน QR คอร์ตที่ไม่มีรายการจองของตนเอง (Negative) | C7: 1. จองคอร์ต 1 เวลา 18:00 2. เปิดหน้า /scan แล้วสแกน QR ของคอร์ต 3 3. ตรวจผลลัพธ์ | D7: court=3 | E7: ระบบแจ้งข้อความ "You do not have a pending booking for this court right now." และไม่เปลี่ยนสถานะใด ๆ | F7: API/MySQL round 2: API rejects mismatched court with 404; UI QR message not checked (only part of workbook case exercised) | G7: ตรวจไม่ได้
A8: TC_CHK_006 | B8: สแกน QR ที่ไม่ใช่หมายเลขคอร์ต (Negative) | C8: 1. เปิดหน้า /scan 2. สแกน QR ที่มีข้อความทั่วไปหรือลิงก์เว็บไซต์ (ไม่ใช่ตัวเลข) 3. ตรวจผลลัพธ์ | D8: QR ที่ decode ได้เป็นข้อความ "https://example.com" | E8: ระบบแจ้งข้อความ "Invalid QR Code. Please scan a valid court QR." และกลับมาโหมดสแกนตามปกติ | G8: รอทดสอบ
A9: TC_CHK_007 | B9: สแกน QR ของการจองที่ถูกยกเลิกแล้ว (Negative) | C9: 1. จองคอร์ต 2 เวลา 18:00 แล้วยกเลิกก่อนเวลา 2. สแกน QR ของคอร์ต 2 เวลา 17:55 3. ตรวจผลลัพธ์ | D9: court=2, สถานะ CANCELLED | E9: ระบบแจ้งว่าไม่มีรายการที่รอเช็กอินสำหรับคอร์ตนี้ และไม่เปลี่ยนสถานะเป็น CHECKED_IN | G9: รอทดสอบ
A10: TC_CHK_008 | B10: สแกนซ้ำหลังเช็กอินสำเร็จ (Edge Case) | C10: 1. สแกน QR เช็กอินสำเร็จแล้ว 2. ไม่ปิดหน้า สแกน QR ของคอร์ตเดิมซ้ำอีกครั้ง | D10: court=2, หลังเช็กอินสำเร็จ | E10: ระบบไม่ส่งคำขอเช็กอินซ้ำ (มีตัวกันการประมวลผลซ้ำ) และไม่เกิดข้อผิดพลาดบนหน้าจอ | G10: รอทดสอบ
A11: TC_CHK_009 | B11: Admin เห็นสถานะเปลี่ยนเป็น CHECKED_IN โดยไม่ต้องรีเฟรช (Positive, A08) | C11: 1. เปิดหน้า /dashboard ของ Admin ค้างไว้ 2. ให้ User สแกน QR เช็กอินสำเร็จ 3. สังเกตหน้าจอ Admin ภายใน 5-10 วินาที | D11: Admin dashboard + booking ของ User | E11: สถานะการจองบนหน้าจอ Admin เปลี่ยนเป็น CHECKED_IN เองโดยไม่ต้องกดรีเฟรช (มี polling ทุก 5 วินาที) | G11: รอทดสอบ
A12: TC_CHK_010 | B12: Countdown ของ Admin เริ่มหลังเช็กอิน (Positive, A08) | C12: 1. ให้ User เช็กอินสำเร็จ 2. ที่หน้าจอ Admin เลือกการจองนั้น 3. สังเกตตัวเลขนับถอยหลัง | D12: booking 18:00-19:00 | E12: หน้าจอ Admin แสดงสถานะใหม่พร้อมเวลานับถอยหลังไปจนถึงเวลาสิ้นสุดการจอง (time_out) และหยุดที่ 00:00 | G12: รอทดสอบ
A13: TC_CHK_011 | B13: Admin กดจบการใช้งานก่อนเวลา (Positive) | C13: 1. มีการจองสถานะ CHECKED_IN 2. กดปุ่มจบการใช้งานและยืนยันในกล่องยืนยัน 3. ตรวจสถานะ | D13: booking สถานะ CHECKED_IN | E13: สถานะเปลี่ยนเป็น COMPLETED และแสดงข้อความ "Booking finished successfully" | G13: รอทดสอบ
A14: TC_CHK_012 | B14: Admin กดจบการใช้งานกับการจองที่ยังไม่เช็กอิน (Negative) | C14: 1. มีการจองสถานะ PENDING 2. กดจบการใช้งานรายการนั้น 3. ตรวจผลลัพธ์ | D14: booking สถานะ PENDING | E14: ระบบตอบกลับ 400 พร้อมข้อความ "Cannot finish. Status is currently PENDING" และสถานะไม่เปลี่ยน | F14: API/MySQL round 2: HTTP 400, PENDING unchanged | G14: ผ่าน
A15: TC_CHK_013 | B15: การจบการใช้งานอัตโนมัติหลังครบ 1 ชั่วโมง (Positive) | C15: 1. จองคอร์ต 2 เวลา 18:00 และเช็กอินสำเร็จ 2. รอจนเวลาเกิน 19:00 ให้ cron ทำงาน 3. ตรวจสถานะ | D15: booking 18:00 ที่เช็กอินแล้ว | E15: ระบบเปลี่ยนสถานะเป็น COMPLETED อัตโนมัติโดยไม่ต้องมีผู้ใช้กดอะไร (งานตามเวลาทำงานได้แม้ไม่มีใครเปิดหน้าเว็บ) | G15: รอทดสอบ
A16: TC_CHK_014 | B16: ผู้ใช้ปฏิเสธสิทธิ์การใช้กล้อง (Edge Case) | C16: 1. เปิดหน้า /scan 2. กด Block เมื่อเบราว์เซอร์ขออนุญาตใช้กล้อง 3. สังเกตหน้าจอ | D16: เบราว์เซอร์ปฏิเสธสิทธิ์กล้อง | E16: หน้าจอแสดงข้อความแนะนำให้อนุญาตสิทธิ์กล้องหรือใช้ช่องทางสำรอง และหน้าเว็บไม่ค้าง | G16: รอทดสอบ
A17: TC_CHK_015 | B17: เช็กอินตรง deadline พอดีต้องถูกปฏิเสธ (Boundary, dev) | C17: 1. จองคอร์ต 2 รอบ 10:00 (deadline 10:15) 2. จำลองเวลา 10:15:00 แล้วสแกนเช็กอิน 3. ตรวจรหัสสถานะและผลในฐานข้อมูล | D17: court=2, รอบ 10:00, สแกนเวลา 10:15:00 | E17: ระบบตอบกลับ 400 พร้อมข้อความ "The check-in period has ended." และสถานะยังเป็น PENDING แม้ cron จะยังไม่เปลี่ยนสถานะ | F17: TypeORM/MySQL mocked time: 400 The check-in period has ended.; remains PENDING; only service/cron path, not physical UI | G17: ตรวจไม่ได้
A18: TC_CHK_016 | B18: เช็กอินที่ 10:14:59 ต้องสำเร็จ (Boundary, dev) | C18: 1. จองคอร์ต 2 รอบ 10:00 2. จำลองเวลา 10:14:59 แล้วสแกนเช็กอิน 3. ตรวจสถานะ | D18: court=2, รอบ 10:00, สแกนเวลา 10:14:59 | E18: ระบบยอมรับและเปลี่ยนสถานะเป็น CHECKED_IN (ช่วงเวลาเดียวกันกับ TC_CHK_015 แต่ต่างกัน 1 วินาที) | F18: TypeORM/MySQL mocked time: 10:14:59 CHECKED_IN; only service/cron path, not physical UI | G18: ตรวจไม่ได้
A19: TC_CHK_017 | B19: เช็กอินเมื่อจองกลางรอบ ใช้ created_at คิด deadline (Boundary, dev) | C19: 1. จองคอร์ต 3 รอบ 10:00 ตอนเวลา 10:30 (created_at = 10:30, deadline = 10:45) 2. ทดสอบเช็กอินที่ 10:44:59 แล้วทดสอบซ้ำที่ 10:45:00 ใน fixture แยก 3. ตรวจผลลัพธ์ทั้งสองครั้ง | D19: รอบ 10:00 ที่จองเวลา 10:30 | E19: 10:44:59 เช็กอินสำเร็จ แต่ 10:45:00 ถูกปฏิเสธ เพราะ deadline คิดจาก max(เวลาเริ่มรอบ, เวลาสร้างการจอง) + 15 นาที | F19: TypeORM/MySQL mocked time: 10:44:59 accepted; 10:45:00 400 The check-in period has ended.; only service/cron path, not physical UI | G19: ตรวจไม่ได้
A20: TC_CHK_018 | B20: รอบที่จบก่อน deadline: เช็กอินได้จนถึงเวลาสิ้นสุดรอบ (Boundary, dev) | C20: 1. จองคอร์ต 1 รอบ 10:00 ตอนเวลา 10:50 (deadline = 11:05 ซึ่งเลยเวลาจบรอบ 11:00) 2. ทดสอบเช็กอินที่ 10:59:59 แล้วทดสอบที่ 11:00:00 ใน fixture แยก 3. ตรวจผลลัพธ์ทั้งสองครั้ง | D20: รอบ 10:00 ที่จองเวลา 10:50 | E20: 10:59:59 เช็กอินสำเร็จ แต่ 11:00:00 ถูกปฏิเสธ เพราะเวลาสิ้นสุดรอบมาเร็วกว่า deadline | F20: TypeORM/MySQL mocked time: 10:59:59 accepted; 11:00:00 400 The check-in period has ended.; only service/cron path, not physical UI | G20: ตรวจไม่ได้
A21: TC_CHK_019 | B21: ข้อมูลเก่าที่ไม่มี created_at ยังคิด deadline จากเวลาเริ่มรอบ (Edge Case, dev) | C21: 1. เตรียมรายการจองเก่า (created_at = null) รอบ 10:00 2. ทดสอบเช็กอินที่ 10:14:59 และ 10:15:00 3. ตรวจผลลัพธ์และค่าที่บันทึก | D21: booking เก่า created_at = null, รอบ 10:00 | E21: ใช้ deadline 10:15 (เวลาเริ่มรอบ + 15 นาที) โดยไม่เกิด Invalid Date และผลการเช็กอินถูกต้องตามขอบเวลา | F21: TypeORM/MySQL mocked time: legacy created_at null: 10:14:59 accepted; 10:15:00 rejected; only service/cron path, not physical UI | G21: ตรวจไม่ได้
A22: TC_CHK_020 | B22: ปรับเวลาที่เครื่องผู้ใช้ให้ช้าหรือเร็ว (Edge Case) | C22: 1. เปลี่ยนเวลาที่เครื่อง client ให้ช้า/เร็วกว่าเวลาจริง 2. พยายามเช็กอินนอกช่วงเวลาที่อนุญาต 3. ตรวจผลลัพธ์และตัวเลขนับถอยหลังบนหน้าจอ | D22: เวลาที่เครื่อง client ถูกแก้ไข | E22: ผู้ใช้ไม่สามารถหลบข้อจำกัดเวลาได้ เพราะกติกาบังคับที่เซิร์ฟเวอร์ และเวลาที่แสดงบนหน้าจอ (countdown) คำนวณจากเวลาปัจจุบัน ไม่ค้างหรือติดลบ | G22: รอทดสอบ
A23: TC_CHK_021 | B23: เปิดหน้าสแกนผ่าน HTTP บนอุปกรณ์จริง (Negative, QR-03) | C23: 1. เปิด http://<lan-ip>:3000/scan บนมือถือ 2. อ่านข้อความที่หน้าจอแสดง 3. ตรวจว่าหน้าจอค้างหรือไม่ | D23: เปิดผ่าน HTTP (ไม่ใช่ HTTPS/localhost) บน Chrome Android หรือ Safari iOS | E23: หน้าแจ้งข้อจำกัดว่ากล้องต้องใช้ HTTPS/localhost พร้อมทางออกจากหน้า ไม่ค้างเงียบ และไม่โชว์กล้องที่ใช้งานไม่ได้โดยไม่อธิบาย (html5-qrcode ต้องมีข้อความหรือ error ที่อ่านได้) | G23: รอทดสอบ
A24: TC_CHK_022 | B24: เปิดหน้าสแกนก่อนข้อมูลการจองโหลดเสร็จ (Edge Case, QR-09) | C24: 1. หน่วง /bookings/me ให้ตอบช้า 2. เปิด /scan แล้วสแกน QR คอร์ตที่มี PENDING ทันที 3. ตรวจข้อความหลังข้อมูลโหลดเสร็จ แล้วสแกนซ้ำ | D24: myBookings ยังว่างเพราะโหลดไม่เสร็จ, QR = 1 | E24: ไม่แจ้งถาวรว่าไม่มีรายการจอง แต่แจ้งว่ากำลังโหลดหรือให้ลองใหม่ และเมื่อข้อมูลมาถึงแล้วสแกนซ้ำสำเร็จ (scan อ่าน pending จาก myBookingsRef) | G24: รอทดสอบ
A25: TC_CHK_023 | B25: ออกจากหน้าหรือกด Back ระหว่างสแกน (Edge Case, QR-10) | C25: 1. เปิด /scan ให้กล้องทำงาน 2. กด Back หรือเปลี่ยนหน้าไปหน้าอื่นทันที 3. ตรวจว่าไฟกล้องดับ แล้วกลับเข้ามาที่ /scan อีกครั้ง | D25: สแกนค้างไว้ 5 วินาทีแล้วกด Back | E25: กล้องหยุดทำงาน (มี scannerRef.current.clear() ใน cleanup) ไฟกล้องดับ ไม่มี DOM scanner ซ้ำหรือคำขอค้าง และเปิดหน้าใหม่ได้ปกติ | G25: รอทดสอบ
A26: TC_CHK_024 | B26: คำขอเช็กอินล้มเหลวหรือเครือข่ายหลุด (Negative, QR-11) | C26: 1. สแกน QR ของคอร์ตที่มี PENDING 2. ตัดเครือข่ายหรือทำให้ POST /bookings/{id}/check-in ตอบ 500 3. เปิดเครือข่ายกลับแล้วสแกนใหม่ | D26: QR = 1, POST /bookings/{id}/check-in ตอบ 500 | E26: หน้าจอไม่แสดงว่าเช็กอินสำเร็จ แจ้งข้อผิดพลาดให้ลองใหม่ และสแกนซ้ำได้จนสำเร็จ โดยสถานะยังเป็น PENDING จนกว่าจะสำเร็จจริง | G26: รอทดสอบ
A27: TC_CHK_025 | B27: ใช้งานกล้องหลังมือถือ แนวนอน แสงน้อย และ QR ย่อขนาด (Edge Case, QR-12) | C27: 1. ใช้กล้องหลังเครื่องจริงสแกนในแนวตั้ง 2. หมุนเป็นแนวนอนและลดแสงลง 3. ย่อ QR ให้เล็กลงแล้วสแกนอีกครั้ง | D27: Chrome Android / Safari iOS, QR ขนาดจริงและย่อ 50% | E27: อ่าน QR ได้หรือแจ้งสถานะที่ชัดเจน ไม่มีภาพค้างหรือค่าที่อ่านได้เป็นขยะ และผู้ใช้กลับมาสแกนใหม่ได้โดยไม่ต้องโหลดหน้าใหม่ทั้งหน้า | G27: รอทดสอบ
A28: TC_CHK_026 | B28: QR ของผู้ดูแลก่อนเวลาเริ่มรอบ ([ยืนยันกติกา], QR-13) | C28: 1. จองรอบ 10:00 ของคอร์ต 1 2. ให้ผู้ดูแลเปิด QR ของคอร์ต 1 เวลา 09:50 3. ให้นักศึกษาสแกน (backend อนุญาตตั้งแต่ 09:45) | D28: รอบ 10:00, ทดสอบเวลา 09:50 (ก่อนเริ่มรอบ 10 นาที) | E28: UI ผู้ดูแลและสิทธิ์ของ backend ต้องสอดคล้องกัน — ถ้า UI ยังรอถึงเวลาเริ่มรอบ ให้บันทึกเป็นข้อขัดแย้ง GAP-03 และใช้ "ตรวจไม่ได้" จนกว่าทีมจะยืนยัน flow การเช็กอินล่วงหน้า | G28: รอทดสอบ
A29: TC_CHK_027 | B29: เช็กอิน 10:45:00 พอดีของรอบที่จองกลางรอบ (Boundary, TIM-06) | C29: 1. จองรอบ 10:00-11:00 ตอนเวลา 10:30 (created_at = 10:30) 2. เช็กอินเวลา 10:45:00 พอดี 3. ตรวจผลลัพธ์ | D29: booking 10:00-11:00 ที่สร้างตอน 10:30, เช็กอิน 10:45:00 | E29: ถูกปฏิเสธ 400 "The check-in period has ended." เพราะ deadline = max(10:00, 10:30) + 15 นาที = 10:45:00 และเวลาที่เท่ากับ deadline ถือว่าหมดสิทธิ์ | F29: TypeORM/MySQL mocked time: 400 The check-in period has ended.; PENDING; only service/cron path, not physical UI | G29: ตรวจไม่ได้
A30: TC_CHK_028 | B30: ช่วง 00:00-06:59 ไทย เมื่อวัน UTC ยังเป็นเมื่อวาน (Boundary, TIM-11) | C30: 1. ตั้งเวลาระบบเป็น 2026-09-22 01:00 +07:00 (วัน UTC ยังเป็น 21) 2. เปิด /booking และเรียก GET /courts/availability แบบไม่ส่ง date 3. เทียบวันและรอบเวลาที่แสดงกับข้อมูลในฐานข้อมูล | D30: เวลาไทย 2026-09-22 01:00, availability โดยไม่มี query date | E30: API และหน้าจอต้องเลือกวันของไทย (22) ไม่ใช่วัน UTC (21) — ข้อควรระวัง: courts.service.getAvailability เมื่อ date เป็น undefined จะไม่กรองวัน จึงต้องยืนยันพฤติกรรมกับทีม (GAP-05) | G30: รอทดสอบ

Sheet 05_REQ-BAN
A1: REQ-BAN: งานอัตโนมัติ ความผิด การแบน และการปลดแบน
A2: Test Case ID | B2: Test Scenario | C2: Test Steps | D2: Test Data | E2: Expected Result | F2: Actual Result | G2: Status
A3: TC_BAN_001 | B3: ระบบยกเลิกอัตโนมัติเมื่อไม่เช็กอินภายใน 15 นาที (Positive, S02) | C3: 1. เตรียมข้อมูลการจองคอร์ต 1 เวลา 18:00 สถานะ PENDING ของผู้ใช้ที่ strikes = 0 2. ปล่อยให้เวลาเกิน 18:15 โดยไม่เช็กอิน 3. ตรวจสถานะการจองและ strikes | D3: booking 18:00, ตรวจที่เวลา 18:15:10 | E3: การจองถูกเปลี่ยนเป็น CANCELLED อัตโนมัติ และ strikes ของผู้ใช้เพิ่มเป็น 1 | G3: รอทดสอบ
A4: TC_BAN_002 | B4: งานอัตโนมัติทำงานโดยไม่มีใครเปิดหน้าเว็บ (Positive, S02) | C4: 1. ปิดเบราว์เซอร์ทั้งหมดและให้ผู้ใช้ล็อกเอาต์ 2. ปล่อยให้เลยเวลา 15 นาที 3. ตรวจสถานะในฐานข้อมูล | D4: ระบบ backend ยังทำงานอยู่ | E4: ระบบยกเลิกการจองและนับความผิดให้ตามเวลา แม้ไม่มีผู้ใช้เปิดหน้าเว็บเลย | G4: รอทดสอบ
A5: TC_BAN_003 | B5: งานอัตโนมัติเรียกซ้ำไม่นับความผิดซ้ำ (Positive, S02) | C5: 1. ให้เกิดการยกเลิกอัตโนมัติ 1 รายการ (strikes = 1) 2. รอให้ cron ทำงานอีก 2-3 รอบ 3. ตรวจ strikes | D5: booking ที่ถูกยกเลิกอัตโนมัติแล้ว | E5: strikes ยังคงเป็น 1 (ไม่ถูกนับซ้ำ) และจำนวนการแบนไม่เกิดขึ้น | F5: TypeORM/MySQL mocked time: cron called three times, one strike and no ban | G5: ผ่าน
A6: TC_BAN_004 | B6: ขอบเวลา 18:14:xx รายการยังไม่ถูกยกเลิก (Boundary) | C6: 1. มีรายการ PENDING เวลา 18:00 2. ตรวจที่เวลา 18:14:30 3. ตรวจสถานะ | D6: ตรวจที่เวลา 18:14:30 | E6: รายการยังเป็น PENDING (ยังไม่ถึงเส้นตาย) และยังไม่มี strikes | F6: TypeORM/MySQL mocked time: 18:14:30 pending, strikes=0; only service/cron path, not physical UI | G6: ตรวจไม่ได้
A7: TC_BAN_005 | B7: ขอบเวลา 18:15:00 รายการถูกยกเลิกและนับความผิด (Boundary) | C7: 1. มีรายการ PENDING เวลา 18:00 2. ตรวจที่เวลา 18:15:00 พอดี 3. ตรวจสถานะและ strikes | D7: ตรวจที่เวลา 18:15:00 | E7: รายการถูกยกเลิกอัตโนมัติและ strikes เพิ่มเป็น 1 ที่ขอบเวลาพอดี | F7: TypeORM/MySQL mocked time: 18:15:00 cancelled, strikes=1; only service/cron path, not physical UI | G7: ตรวจไม่ได้
A8: TC_BAN_006 | B8: ความผิดครั้งแรกยังไม่ถูกแบน (Positive) | C8: 1. ทำให้เกิดความผิดครั้งที่ 1 2. ตรวจค่า strikes และ banned_until | D8: ผู้ใช้ที่ยังไม่มีประวัติความผิด | E8: strikes = 1 และ banned_until เป็น null (ยังไม่ถูกแบน) | F8: TypeORM/MySQL mocked time: first strike=1, no ban | G8: ผ่าน
A9: TC_BAN_007 | B9: ความผิดครั้งที่สองแบนทันที 24 ชั่วโมง (Positive) | C9: 1. ผู้ใช้มี strikes = 1 จากวันก่อน 2. ทำให้เกิดความผิดอีก 1 ครั้ง 3. ตรวจ banned_until | D9: ผู้ใช้ที่ strikes = 1 | E9: strikes = 2 และ banned_until มีค่าเท่ากับเวลาที่เกิดความผิดครั้งที่สอง + 24 ชั่วโมง | F9: TypeORM/MySQL mocked time: second strike=2, ban +24h | G9: ผ่าน
A10: TC_BAN_008 | B10: ความผิดสะสมข้ามวัน (Positive) | C10: 1. ทำให้เกิดความผิดวันที่ 1 (strikes = 1) 2. ทำให้เกิดความผิดวันที่ 2 3. ตรวจว่าแบนเกิดขึ้นในการผิดครั้งที่สอง | D10: ความผิดคนละวัน ไม่ใช่การนับรีเซ็ตรายวัน | E10: ระบบนับความผิดสะสมข้ามวัน และแบนทันทีเมื่อครบ 2 ครั้ง แม้เกิดคนละวัน | F10: TypeORM/MySQL mocked time: strike 1 Sep 27; strike 2 Sep 28; ban +24h | G10: ผ่าน
A11: TC_BAN_009 | B11: รายการค้างหลายรายการของคนเดียวกันถูกนับครบ (Positive, Regression) | C11: 1. เตรียมรายการ PENDING ของผู้ใช้คนเดียว 2 รายการในคนละวัน (เช่น วันที่ 15 และ 16) 2. ให้ระบบประมวลผลงานอัตโนมัติในวันที่ 17 3. ตรวจ strikes และ banned_until | D11: 2 รายการค้างของ stu_id เดียวกัน | E11: ทั้งสองรายการถูกยกเลิก และ strikes = 2 (นับครบทั้งสองรายการ ไม่ใช่ 1) พร้อมถูกแบน 24 ชั่วโมง | F11: TypeORM/MySQL mocked time: two rows cancelled, strikes=2, banned | G11: ผ่าน
A12: TC_BAN_010 | B12: ยกเลิกสายและงานอัตโนมัติในรายการเดียวกันไม่นับซ้ำ (Positive, S02) | C12: 1. ผู้ใช้กดยกเลิกสาย (หลังเส้นตาย) รายการหนึ่ง 2. ให้ cron ทำงานต่อทันที 3. ตรวจ strikes | D12: booking 1 รายการ ที่ถูกยกเลิกสาย | E12: รายการเดียวกันถูกนับความผิดเพียง 1 ครั้ง (ไม่นับซ้ำจากการยกเลิกสายและการทำงานของ cron) | F12: TypeORM/MySQL mocked time: late cancel + cron remains 1 strike | G12: ผ่าน
A13: TC_BAN_011 | B13: ผู้ใช้ที่ถูกแบนไม่สามารถจองได้ (Negative) | C13: 1. ให้ผู้ใช้ถูกแบน (strikes = 2) 2. พยายามจองคอร์ดใหม่ 3. ตรวจผลลัพธ์ | D13: ผู้ใช้ที่มี banned_until อยู่ในอนาคต | E13: ระบบตอบกลับ 400 พร้อมข้อความ "Your account is currently banned from booking courts." และไม่มีการจองถูกสร้าง | F13: API/MySQL round 2: HTTP 400; no new booking | G13: ผ่าน
A14: TC_BAN_012 | B14: พ้นแบนแล้วระบบปลดแบนอัตโนมัติ (Positive) | C14: 1. ตั้ง banned_until ให้เป็นเวลาในอดีต 2. ให้ cron ทำงาน 3. ตรวจค่าของ banned_until และ strikes | D14: banned_until = เมื่อวาน | E14: banned_until ถูกตั้งเป็น null และ strikes ถูกรีเซ็ตเป็น 0 อัตโนมัติ | F14: API/MySQL round 2: ban cleared by ban-status, automatic cron path not exercised (only part of workbook case exercised) | G14: ตรวจไม่ได้
A15: TC_BAN_013 | B15: พ้นแบนแล้วเข้าใช้งานระบบ ตรวจสถานะผ่าน API (Positive) | C15: 1. ตั้ง banned_until ให้เป็นเวลาในอดีต 2. เข้าสู่ระบบแล้วเปิดหน้า /dashboard 3. ตรวจผลจาก GET /users/me/ban-status | D15: บัญชีที่พ้นแบนแล้ว | E15: API คืนค่า isBanned = false, strikes = 0 และฐานข้อมูลถูกล้างค่าแบนให้แล้วโดยไม่ต้องรอ cron | F15: API/MySQL round 2: 200 isBanned=false, strikes=0, DB cleared | G15: ผ่าน
A16: TC_BAN_014 | B16: Popup แจ้งการแบนแสดงเมื่อเข้าใช้งาน (Positive, U08) | C16: 1. ให้บัญชีผู้ใช้ถูกแบน 2. เข้าสู่ระบบและเปิดหน้า /dashboard 3. ตรวจหน้าต่างที่เด้งขึ้น | D16: ผู้ใช้ที่มี banned_until อยู่ในอนาคต | E16: แสดง Popup หัวข้อ "บัญชีของคุณถูกระงับการใช้งาน" พร้อมวัน-เวลาพ้นแบน (รูปแบบ th-TH) และปุ่ม "รับทราบ" ตามข้อกำหนด U08 | G16: รอทดสอบ
A17: TC_BAN_015 | B17: Popup แบนอัปเดตตามข้อมูลระบบส่วนกลาง (Positive, U08) | C17: 1. แสดง Popup แบนค้างไว้ 2. ให้ระบบปลดแบน (admin หรือ cron) 3. ตรวจข้อความบน Popup หลังปิดและเปิดใหม่ | D17: ผู้ใช้ที่ถูกปลดแบน | E17: เมื่อสถานะจากเซิร์ฟเวอร์เปลี่ยนเป็นไม่ถูกแบน Popup จะไม่แสดงอีก และไม่ค้างข้อมูลเดิม (อ้างข้อมูลจาก API ส่วนกลาง ไม่ใช่ค่าที่ค้างในเบราว์เซอร์) | G17: รอทดสอบ
A18: TC_BAN_016 | B18: Admin ไม่ถูกแบนและไม่เห็น Popup (Negative) | C18: 1. เข้าสู่ระบบด้วยบัญชี Admin 2. ตรวจ GET /users/me/ban-status 3. ตรวจหน้าจอว่าไม่ปรากฏ Popup แบน | D18: บัญชี Admin ที่ระบบ seed (admin / password ตาม users.service.ts) | E18: API คืน isBanned = false, strikes = 0 และหน้าเว็บของ Admin ไม่แสดง Popup แบน | G18: รอทดสอบ
A19: TC_BAN_017 | B19: ความผิดของผู้ใช้แต่ละคนไม่ปะปนกัน (Positive) | C19: 1. ให้ผู้ใช้ A ถูกแบน 2. ให้ผู้ใช้ B จองคอร์ดตามปกติ 3. ตรวจผลลัพธ์ของผู้ใช้ B | D19: ผู้ใช้ A ถูกแบน / ผู้ใช้ B ปกติ | E19: ผู้ใช้ B จองได้ตามปกติ (ไม่ถูกปฏิเสธ) และค่า strikes ของ A และ B แยกจากกัน | F19: API/MySQL round 2: B booked while A banned; strikes A=2/B=0 | G19: ผ่าน
A20: TC_BAN_018 | B20: งานอัตโนมัติยกเลิกรอบที่ deadline เลยเวลาจบรอบ โดยไม่นับความผิด (Positive, dev) | C20: 1. เตรียมรายการ PENDING รอบ 10:00 ที่จองตอน 10:50 (deadline 11:05 > เวลาจบรอบ 11:00) 2. ให้ cron ทำงานหลัง 11:00 3. ตรวจสถานะและ strikes | D20: รายการรอบสั้น (deadline > end) | E20: รายการถูกยกเลิกที่ min(deadline, end) = 11:00 และ strikes ไม่เพิ่ม (เพราะ deadline เกินเวลาสิ้นสุดรอบ) | F20: TypeORM/MySQL mocked time: short round ended, no strike | G20: ผ่าน
A21: TC_BAN_019 | B21: กรณี deadline เท่ากับเวลาสิ้นสุดรอบพอดี (Boundary, dev) | C21: 1. เตรียมรายการ PENDING ที่ deadline = เวลาสิ้นสุดรอบ 2. ให้ cron ทำงาน 3. ตรวจสถานะและ strikes | D21: รายการที่ deadline == end | E21: ระบบยกเลิกพร้อมเพิ่ม strike 1 ครั้ง ตามเงื่อนไขที่ทดสอบได้ (บันทึกผลจริงที่เกิดขึ้นและยืนยันกติกากับทีม) | F21: TypeORM/MySQL mocked time: deadline equals end, strike 1 | G21: ผ่าน
